Workbook
Name table1C: posting!$P$4:$S$21
Name most_col_s: data2!$I$3:$I$250
Name PG2LC: data2!$AF$3:$AF$250
Name most_col_b: data2!$K$3:$K$250
Name JI: job!$D$2:$D$250
Name jd_C: key_job!$AZ$2:$AZ$41
Name JOBPROFILETO8: key!$J$3:$L$27
Name PG3CS: data2!$AI$3:$AI$250
Name jobdict: key_job!$A$2:$A$41
Name change_col_s: data2!$S$3:$S$250
Name change_col_c: data2!$T$3:$T$250
Name JPM3_: data2!$EY$3:$EY$250
Name Nama: data2!$A$3:$A$250
Name table3I: posting!$F$55:$I$92
Name tableI1: posting!$F$4:$I$23
Name jd_I: key_job!$AX$2:$AX$41
Name jd_D: key_job!$AW$2:$AW$41
Name PG1MS: data2!$AA$3:$AA$250
Name cek1_: data2!$BJ$3:$BJ$250
Name unique: data2!$DQ$3:$DQ$250
Name most_col_i: data2!$H$3:$H$250
Name KELEMAHAN: profile!$A$57:$Y$60
Name PG1MC: data2!$AB$3:$AB$250
Name MmExcelLinker_2BEC1165_5F5C_43B8_AB34_B520A81EDF06: dash_mjpm!$A$2:$L$14
Name lead_styles: profile!$A$133:$R$136
Name Posisi: data2!$E$3:$E$250
Name onejob1: onejob!$A$1:$A$250
Name table1S: posting!$K$4:$N$24
Name PG2LS: data2!$AE$3:$AE$250
Name tableD1: posting!$A$4:$D$25
Name table2I: posting!$F$30:$I$49
Name table3S: posting!$K$55:$N$94
Name kekuatan_e: profile_eng!$A$51:$J$54
Name KEKUATAN: profile!$A$51:$Y$54
Name most_col_d: data2!$G$3:$G$250
Name table2C: posting!$P$30:$S$47
Name most_col_c: data2!$J$3:$J$250
Name PG2LD: data2!$AC$3:$AC$250
Name IMJPM2: imjpm!$B$1:$B$250
Name jd_S: key_job!$AY$2:$AY$41
Name Tujuan: data2!$F$3:$F$250
Name CEKGRAF: data2!$DP$3:$DP$250
Name JPM2_: data2!$ES$3:$ES$250
Name MmExcelLinker_4BE19340_872D_4B1E_BE01_1898BB3742AA: main!$V$11
Name TABLE_D: profile_detail!$B$2:$L$13
Name tabel_jpm: tabeljpm!$A$4:$I$11
Name PG1MI: data2!$Z$3:$Z$250
Name prof3: data2!$DO$3:$DO$250
Name tabel_profil: profile!$A$3:$M$42
Name table3C: posting!$P$55:$S$94
Name Kelamin: data2!$B$3:$B$250
Name JC: job!$F$2:$F$250
Name karakteristik: profile!$A$139:$S$142
Name Job_Title: job!$B$2:$B$250
Name least_col_c: data2!$O$3:$O$250
Name least_col_i: data2!$M$3:$M$250
Name cek2_: data2!$CL$3:$CL$250
Name Z_0D9D62F5_B2A7_45DB_A015_044C4D3A4C2D_.wvu.PrintArea: graph!$A$4:$P$35
Name table2D: posting!$A$30:$D$50
Name profil_e: profile_eng!$A$3:$I$42

Sheet log
A1: username | B1: serial_no
A2: HRDBC | B2: BC2026

Sheet main
F13: Username | H13: =log!A2 -> HRDBC
F14: Serial No | H14: =log!B2 -> BC2026

Sheet data
B1: Jenis | D1: Tanggal | G1: Most | L1: Least | Q1: Change | V1: Cek | AA1: =MATCH(AA2,Job_Title,0) -> 13
A2: Nama | B2: Kelamin | C2: Nomor | D2: Tes | E2: Posisi | F2: Tujuan | G2: D | H2: I | I2: S | J2: C | K2: B | L2: D | M2: I | N2: S | O2: C | P2: B | Q2: D | R2: I | S2: S | T2: C | U2: B | V2: M | W2: L | X2: Grafik1 | Y2: Grafik2 | Z2: Grafik3 | AA2: Kepatuhan Internal
A3: Andre Setiawan | B3: Pria | D3: 44291 | F3: profiling | G3: 2 | H3: 0 | I3: 4 | J3: 10 | K3: 8 | L3: 6 | M3: 7 | N3: 3 | O3: 1 | P3: 7 | Q3: -4 | R3: -7 | S3: 1 | T3: 9 | V3: =SUM(G3:U3) -> 47 | W3: =SUM(L3:P3) -> 24 | X3: =IF(VLOOKUP(data2!BJ3,misc!$A$8:$B$11,2,0)="normal",data2!BK3,VLOOKUP(data2!BJ3,misc!$A$8:$B$11,2,0)) -> C | Y3: =IF(VLOOKUP(data2!CL3,misc!$A$8:$B$11,2,0)="normal",data2!CM3,VLOOKUP(data2!CL3,misc!$A$8:$B$11,2,0)) -> CS | Z3: =IF(VLOOKUP(data2!DN3,misc!$A$8:$B$11,2,0)="normal",data2!DO3,VLOOKUP(data2!DN3,misc!$A$8:$B$11,2,0)) -> CS | AA3: =IF(ISERROR(AVERAGE(INDEX(JPM1_,ROW(A3)-2),(INDEX(JPM2_,ROW(A3)-2),(INDEX(JPM3_,ROW(A3)-2)))))=TRUE,"N/A",AVERAGE(INDEX(JPM1_,ROW(A3)-2),(INDEX(JPM2_,ROW(A3)-2),(INDEX(JPM3_,ROW(A3)-2))))) -> #ERROR!
A4: Helmi Kurniawan | B4: Pria | F4: profiling | G4: 3 | H4: 3 | I4: 7 | J4: 4 | K4: 7 | L4: 7 | M4: 4 | N4: 2 | O4: 6 | P4: 5 | Q4: -4 | R4: -1 | S4: 5 | T4: -2 | V4: =SUM(G4:T4) -> 46 | W4: =SUM(L4:P4) -> 24 | X4: =IF(VLOOKUP(data2!BJ4,misc!$A$8:$B$11,2,0)="normal",data2!BK4,VLOOKUP(data2!BJ4,misc!$A$8:$B$11,2,0)) -> SC | Y4: =IF(VLOOKUP(data2!CL4,misc!$A$8:$B$11,2,0)="normal",data2!CM4,VLOOKUP(data2!CL4,misc!$A$8:$B$11,2,0)) -> SCI | Z4: =IF(VLOOKUP(data2!DN4,misc!$A$8:$B$11,2,0)="normal",data2!DO4,VLOOKUP(data2!DN4,misc!$A$8:$B$11,2,0)) -> SC | AA4: =IF(ISERROR(AVERAGE(INDEX(JPM1_,ROW(A4)-2),(INDEX(JPM2_,ROW(A4)-2),(INDEX(JPM3_,ROW(A4)-2)))))=TRUE,"N/A",AVERAGE(INDEX(JPM1_,ROW(A4)-2),(INDEX(JPM2_,ROW(A4)-2),(INDEX(JPM3_,ROW(A4)-2))))) -> #ERROR!
A5: Indah Nopitasari | B5: Wanita | F5: profiling | G5: 0 | H5: 1 | I5: 11 | J5: 4 | K5: 8 | L5: 16 | M5: 3 | N5: 0 | O5: 2 | P5: 3 | Q5: -16 | R5: -2 | S5: 11 | T5: 2 | V5: =SUM(G5:T5) -> 43 | W5: =SUM(L5:P5) -> 24 | X5: =IF(VLOOKUP(data2!BJ5,misc!$A$8:$B$11,2,0)="normal",data2!BK5,VLOOKUP(data2!BJ5,misc!$A$8:$B$11,2,0)) -> SC | Y5: =IF(VLOOKUP(data2!CL5,misc!$A$8:$B$11,2,0)="normal",data2!CM5,VLOOKUP(data2!CL5,misc!$A$8:$B$11,2,0)) -> SCI | Z5: =IF(VLOOKUP(data2!DN5,misc!$A$8:$B$11,2,0)="normal",data2!DO5,VLOOKUP(data2!DN5,misc!$A$8:$B$11,2,0)) -> SC | AA5: =IF(ISERROR(AVERAGE(INDEX(JPM1_,ROW(A5)-2),(INDEX(JPM2_,ROW(A5)-2),(INDEX(JPM3_,ROW(A5)-2)))))=TRUE,"N/A",AVERAGE(INDEX(JPM1_,ROW(A5)-2),(INDEX(JPM2_,ROW(A5)-2),(INDEX(JPM3_,ROW(A5)-2))))) -> #ERROR!
A6: Ayub Putra Utama | B6: Pria | F6: profiling | G6: 3 | H6: 4 | I6: 8 | J6: 2 | K6: 7 | L6: 7 | M6: 6 | N6: 1 | O6: 2 | P6: 8 | Q6: -4 | R6: -2 | S6: 7 | T6: 0 | V6: =SUM(G6:T6) -> 49 | W6: =SUM(L6:P6) -> 24 | X6: =IF(VLOOKUP(data2!BJ6,misc!$A$8:$B$11,2,0)="normal",data2!BK6,VLOOKUP(data2!BJ6,misc!$A$8:$B$11,2,0)) -> SI | Y6: =IF(VLOOKUP(data2!CL6,misc!$A$8:$B$11,2,0)="normal",data2!CM6,VLOOKUP(data2!CL6,misc!$A$8:$B$11,2,0)) -> SC | Z6: =IF(VLOOKUP(data2!DN6,misc!$A$8:$B$11,2,0)="normal",data2!DO6,VLOOKUP(data2!DN6,misc!$A$8:$B$11,2,0)) -> SC | AA6: =IF(ISERROR(AVERAGE(INDEX(JPM1_,ROW(A6)-2),(INDEX(JPM2_,ROW(A6)-2),(INDEX(JPM3_,ROW(A6)-2)))))=TRUE,"N/A",AVERAGE(INDEX(JPM1_,ROW(A6)-2),(INDEX(JPM2_,ROW(A6)-2),(INDEX(JPM3_,ROW(A6)-2))))) -> #ERROR!
X7: =IF(VLOOKUP(data2!BJ7,misc!$A$8:$B$11,2,0)="normal",data2!BK7,VLOOKUP(data2!BJ7,misc!$A$8:$B$11,2,0)) -> undershift | Y7: =IF(VLOOKUP(data2!CL7,misc!$A$8:$B$11,2,0)="normal",data2!CM7,VLOOKUP(data2!CL7,misc!$A$8:$B$11,2,0)) -> uppershift | Z7: =IF(VLOOKUP(data2!DN7,misc!$A$8:$B$11,2,0)="normal",data2!DO7,VLOOKUP(data2!DN7,misc!$A$8:$B$11,2,0)) -> tight profile | AA7: =IF(ISERROR(AVERAGE(INDEX(JPM1_,ROW(A7)-2),(INDEX(JPM2_,ROW(A7)-2),(INDEX(JPM3_,ROW(A7)-2)))))=TRUE,"N/A",AVERAGE(INDEX(JPM1_,ROW(A7)-2),(INDEX(JPM2_,ROW(A7)-2),(INDEX(JPM3_,ROW(A7)-2))))) -> #ERROR!
X8: =IF(VLOOKUP(data2!BJ8,misc!$A$8:$B$11,2,0)="normal",data2!BK8,VLOOKUP(data2!BJ8,misc!$A$8:$B$11,2,0)) -> undershift | Y8: =IF(VLOOKUP(data2!CL8,misc!$A$8:$B$11,2,0)="normal",data2!CM8,VLOOKUP(data2!CL8,misc!$A$8:$B$11,2,0)) -> uppershift | Z8: =IF(VLOOKUP(data2!DN8,misc!$A$8:$B$11,2,0)="normal",data2!DO8,VLOOKUP(data2!DN8,misc!$A$8:$B$11,2,0)) -> tight profile | AA8: =IF(ISERROR(AVERAGE(INDEX(JPM1_,ROW(A8)-2),(INDEX(JPM2_,ROW(A8)-2),(INDEX(JPM3_,ROW(A8)-2)))))=TRUE,"N/A",AVERAGE(INDEX(JPM1_,ROW(A8)-2),(INDEX(JPM2_,ROW(A8)-2),(INDEX(JPM3_,ROW(A8)-2))))) -> #ERROR!
X9: =IF(VLOOKUP(data2!BJ9,misc!$A$8:$B$11,2,0)="normal",data2!BK9,VLOOKUP(data2!BJ9,misc!$A$8:$B$11,2,0)) -> undershift | Y9: =IF(VLOOKUP(data2!CL9,misc!$A$8:$B$11,2,0)="normal",data2!CM9,VLOOKUP(data2!CL9,misc!$A$8:$B$11,2,0)) -> uppershift | Z9: =IF(VLOOKUP(data2!DN9,misc!$A$8:$B$11,2,0)="normal",data2!DO9,VLOOKUP(data2!DN9,misc!$A$8:$B$11,2,0)) -> tight profile | AA9: =IF(ISERROR(AVERAGE(INDEX(JPM1_,ROW(A9)-2),(INDEX(JPM2_,ROW(A9)-2),(INDEX(JPM3_,ROW(A9)-2)))))=TRUE,"N/A",AVERAGE(INDEX(JPM1_,ROW(A9)-2),(INDEX(JPM2_,ROW(A9)-2),(INDEX(JPM3_,ROW(A9)-2))))) -> #ERROR!
X10: =IF(VLOOKUP(data2!BJ10,misc!$A$8:$B$11,2,0)="normal",data2!BK10,VLOOKUP(data2!BJ10,misc!$A$8:$B$11,2,0)) -> undershift | Y10: =IF(VLOOKUP(data2!CL10,misc!$A$8:$B$11,2,0)="normal",data2!CM10,VLOOKUP(data2!CL10,misc!$A$8:$B$11,2,0)) -> uppershift | Z10: =IF(VLOOKUP(data2!DN10,misc!$A$8:$B$11,2,0)="normal",data2!DO10,VLOOKUP(data2!DN10,misc!$A$8:$B$11,2,0)) -> tight profile | AA10: =IF(ISERROR(AVERAGE(INDEX(JPM1_,ROW(A10)-2),(INDEX(JPM2_,ROW(A10)-2),(INDEX(JPM3_,ROW(A10)-2)))))=TRUE,"N/A",AVERAGE(INDEX(JPM1_,ROW(A10)-2),(INDEX(JPM2_,ROW(A10)-2),(INDEX(JPM3_,ROW(A10)-2))))) -> #ERROR!
X11: =IF(VLOOKUP(data2!BJ11,misc!$A$8:$B$11,2,0)="normal",data2!BK11,VLOOKUP(data2!BJ11,misc!$A$8:$B$11,2,0)) -> undershift | Y11: =IF(VLOOKUP(data2!CL11,misc!$A$8:$B$11,2,0)="normal",data2!CM11,VLOOKUP(data2!CL11,misc!$A$8:$B$11,2,0)) -> uppershift | Z11: =IF(VLOOKUP(data2!DN11,misc!$A$8:$B$11,2,0)="normal",data2!DO11,VLOOKUP(data2!DN11,misc!$A$8:$B$11,2,0)) -> tight profile | AA11: =IF(ISERROR(AVERAGE(INDEX(JPM1_,ROW(A11)-2),(INDEX(JPM2_,ROW(A11)-2),(INDEX(JPM3_,ROW(A11)-2)))))=TRUE,"N/A",AVERAGE(INDEX(JPM1_,ROW(A11)-2),(INDEX(JPM2_,ROW(A11)-2),(INDEX(JPM3_,ROW(A11)-2))))) -> #ERROR!
X12: =IF(VLOOKUP(data2!BJ12,misc!$A$8:$B$11,2,0)="normal",data2!BK12,VLOOKUP(data2!BJ12,misc!$A$8:$B$11,2,0)) -> undershift | Y12: =IF(VLOOKUP(data2!CL12,misc!$A$8:$B$11,2,0)="normal",data2!CM12,VLOOKUP(data2!CL12,misc!$A$8:$B$11,2,0)) -> uppershift | Z12: =IF(VLOOKUP(data2!DN12,misc!$A$8:$B$11,2,0)="normal",data2!DO12,VLOOKUP(data2!DN12,misc!$A$8:$B$11,2,0)) -> tight profile | AA12: =IF(ISERROR(AVERAGE(INDEX(JPM1_,ROW(A12)-2),(INDEX(JPM2_,ROW(A12)-2),(INDEX(JPM3_,ROW(A12)-2)))))=TRUE,"N/A",AVERAGE(INDEX(JPM1_,ROW(A12)-2),(INDEX(JPM2_,ROW(A12)-2),(INDEX(JPM3_,ROW(A12)-2))))) -> #ERROR!
X13: =IF(VLOOKUP(data2!BJ13,misc!$A$8:$B$11,2,0)="normal",data2!BK13,VLOOKUP(data2!BJ13,misc!$A$8:$B$11,2,0)) -> undershift | Y13: =IF(VLOOKUP(data2!CL13,misc!$A$8:$B$11,2,0)="normal",data2!CM13,VLOOKUP(data2!CL13,misc!$A$8:$B$11,2,0)) -> uppershift | Z13: =IF(VLOOKUP(data2!DN13,misc!$A$8:$B$11,2,0)="normal",data2!DO13,VLOOKUP(data2!DN13,misc!$A$8:$B$11,2,0)) -> tight profile | AA13: =IF(ISERROR(AVERAGE(INDEX(JPM1_,ROW(A13)-2),(INDEX(JPM2_,ROW(A13)-2),(INDEX(JPM3_,ROW(A13)-2)))))=TRUE,"N/A",AVERAGE(INDEX(JPM1_,ROW(A13)-2),(INDEX(JPM2_,ROW(A13)-2),(INDEX(JPM3_,ROW(A13)-2))))) -> #ERROR!
X14: =IF(VLOOKUP(data2!BJ14,misc!$A$8:$B$11,2,0)="normal",data2!BK14,VLOOKUP(data2!BJ14,misc!$A$8:$B$11,2,0)) -> undershift | Y14: =IF(VLOOKUP(data2!CL14,misc!$A$8:$B$11,2,0)="normal",data2!CM14,VLOOKUP(data2!CL14,misc!$A$8:$B$11,2,0)) -> uppershift | Z14: =IF(VLOOKUP(data2!DN14,misc!$A$8:$B$11,2,0)="normal",data2!DO14,VLOOKUP(data2!DN14,misc!$A$8:$B$11,2,0)) -> tight profile | AA14: =IF(ISERROR(AVERAGE(INDEX(JPM1_,ROW(A14)-2),(INDEX(JPM2_,ROW(A14)-2),(INDEX(JPM3_,ROW(A14)-2)))))=TRUE,"N/A",AVERAGE(INDEX(JPM1_,ROW(A14)-2),(INDEX(JPM2_,ROW(A14)-2),(INDEX(JPM3_,ROW(A14)-2))))) -> #ERROR!
X15: =IF(VLOOKUP(data2!BJ15,misc!$A$8:$B$11,2,0)="normal",data2!BK15,VLOOKUP(data2!BJ15,misc!$A$8:$B$11,2,0)) -> undershift | Y15: =IF(VLOOKUP(data2!CL15,misc!$A$8:$B$11,2,0)="normal",data2!CM15,VLOOKUP(data2!CL15,misc!$A$8:$B$11,2,0)) -> uppershift | Z15: =IF(VLOOKUP(data2!DN15,misc!$A$8:$B$11,2,0)="normal",data2!DO15,VLOOKUP(data2!DN15,misc!$A$8:$B$11,2,0)) -> tight profile | AA15: =IF(ISERROR(AVERAGE(INDEX(JPM1_,ROW(A15)-2),(INDEX(JPM2_,ROW(A15)-2),(INDEX(JPM3_,ROW(A15)-2)))))=TRUE,"N/A",AVERAGE(INDEX(JPM1_,ROW(A15)-2),(INDEX(JPM2_,ROW(A15)-2),(INDEX(JPM3_,ROW(A15)-2))))) -> #ERROR!
X16: =IF(VLOOKUP(data2!BJ16,misc!$A$8:$B$11,2,0)="normal",data2!BK16,VLOOKUP(data2!BJ16,misc!$A$8:$B$11,2,0)) -> undershift | Y16: =IF(VLOOKUP(data2!CL16,misc!$A$8:$B$11,2,0)="normal",data2!CM16,VLOOKUP(data2!CL16,misc!$A$8:$B$11,2,0)) -> uppershift | Z16: =IF(VLOOKUP(data2!DN16,misc!$A$8:$B$11,2,0)="normal",data2!DO16,VLOOKUP(data2!DN16,misc!$A$8:$B$11,2,0)) -> tight profile | AA16: =IF(ISERROR(AVERAGE(INDEX(JPM1_,ROW(A16)-2),(INDEX(JPM2_,ROW(A16)-2),(INDEX(JPM3_,ROW(A16)-2)))))=TRUE,"N/A",AVERAGE(INDEX(JPM1_,ROW(A16)-2),(INDEX(JPM2_,ROW(A16)-2),(INDEX(JPM3_,ROW(A16)-2))))) -> #ERROR!
X17: =IF(VLOOKUP(data2!BJ17,misc!$A$8:$B$11,2,0)="normal",data2!BK17,VLOOKUP(data2!BJ17,misc!$A$8:$B$11,2,0)) -> undershift | Y17: =IF(VLOOKUP(data2!CL17,misc!$A$8:$B$11,2,0)="normal",data2!CM17,VLOOKUP(data2!CL17,misc!$A$8:$B$11,2,0)) -> uppershift | Z17: =IF(VLOOKUP(data2!DN17,misc!$A$8:$B$11,2,0)="normal",data2!DO17,VLOOKUP(data2!DN17,misc!$A$8:$B$11,2,0)) -> tight profile | AA17: =IF(ISERROR(AVERAGE(INDEX(JPM1_,ROW(A17)-2),(INDEX(JPM2_,ROW(A17)-2),(INDEX(JPM3_,ROW(A17)-2)))))=TRUE,"N/A",AVERAGE(INDEX(JPM1_,ROW(A17)-2),(INDEX(JPM2_,ROW(A17)-2),(INDEX(JPM3_,ROW(A17)-2))))) -> #ERROR!
X18: =IF(VLOOKUP(data2!BJ18,misc!$A$8:$B$11,2,0)="normal",data2!BK18,VLOOKUP(data2!BJ18,misc!$A$8:$B$11,2,0)) -> undershift | Y18: =IF(VLOOKUP(data2!CL18,misc!$A$8:$B$11,2,0)="normal",data2!CM18,VLOOKUP(data2!CL18,misc!$A$8:$B$11,2,0)) -> uppershift | Z18: =IF(VLOOKUP(data2!DN18,misc!$A$8:$B$11,2,0)="normal",data2!DO18,VLOOKUP(data2!DN18,misc!$A$8:$B$11,2,0)) -> tight profile | AA18: =IF(ISERROR(AVERAGE(INDEX(JPM1_,ROW(A18)-2),(INDEX(JPM2_,ROW(A18)-2),(INDEX(JPM3_,ROW(A18)-2)))))=TRUE,"N/A",AVERAGE(INDEX(JPM1_,ROW(A18)-2),(INDEX(JPM2_,ROW(A18)-2),(INDEX(JPM3_,ROW(A18)-2))))) -> #ERROR!
... X38: =IF(VLOOKUP(data2!BJ38,misc!$A$8:$B$11,2,0)="normal",data2!BK38,VLOOKUP(data2!BJ38,misc!$A$8:$B$11,2,0)) -> undershift | Y38: =IF(VLOOKUP(data2!CL38,misc!$A$8:$B$11,2,0)="normal",data2!CM38,VLOOKUP(data2!CL38,misc!$A$8:$B$11,2,0)) -> uppershift | Z38: =IF(VLOOKUP(data2!DN38,misc!$A$8:$B$11,2,0)="normal",data2!DO38,VLOOKUP(data2!DN38,misc!$A$8:$B$11,2,0)) -> tight profile | AA38: =IF(ISERROR(AVERAGE(INDEX(JPM1_,ROW(A38)-2),(INDEX(JPM2_,ROW(A38)-2),(INDEX(JPM3_,ROW(A38)-2)))))=TRUE,"N/A",AVERAGE(INDEX(JPM1_,ROW(A38)-2),(INDEX(JPM2_,ROW(A38)-2),(INDEX(JPM3_,ROW(A38)-2))))) -> #ERROR!
X39: =IF(VLOOKUP(data2!BJ39,misc!$A$8:$B$11,2,0)="normal",data2!BK39,VLOOKUP(data2!BJ39,misc!$A$8:$B$11,2,0)) -> #ERROR! | Y39: =IF(VLOOKUP(data2!CL39,misc!$A$8:$B$11,2,0)="normal",data2!CM39,VLOOKUP(data2!CL39,misc!$A$8:$B$11,2,0)) -> #ERROR! | Z39: =IF(VLOOKUP(data2!DN39,misc!$A$8:$B$11,2,0)="normal",data2!DO39,VLOOKUP(data2!DN39,misc!$A$8:$B$11,2,0)) -> #ERROR! | AA39: =IF(ISERROR(AVERAGE(INDEX(JPM1_,ROW(#REF!)-2),(INDEX(JPM2_,ROW(#REF!)-2),(INDEX(JPM3_,ROW(#REF!)-2)))))=TRUE,"N/A",AVERAGE(INDEX(JPM1_,ROW(#REF!)-2),(INDEX(JPM2_,ROW(#REF!)-2),(INDEX(JPM3_,ROW(#REF!)-2))))) -> #ERROR!
X40: =IF(VLOOKUP(data2!BJ40,misc!$A$8:$B$11,2,0)="normal",data2!BK40,VLOOKUP(data2!BJ40,misc!$A$8:$B$11,2,0)) -> undershift | Y40: =IF(VLOOKUP(data2!CL40,misc!$A$8:$B$11,2,0)="normal",data2!CM40,VLOOKUP(data2!CL40,misc!$A$8:$B$11,2,0)) -> uppershift | Z40: =IF(VLOOKUP(data2!DN40,misc!$A$8:$B$11,2,0)="normal",data2!DO40,VLOOKUP(data2!DN40,misc!$A$8:$B$11,2,0)) -> tight profile | AA40: =IF(ISERROR(AVERAGE(INDEX(JPM1_,ROW(A40)-2),(INDEX(JPM2_,ROW(A40)-2),(INDEX(JPM3_,ROW(A40)-2)))))=TRUE,"N/A",AVERAGE(INDEX(JPM1_,ROW(A40)-2),(INDEX(JPM2_,ROW(A40)-2),(INDEX(JPM3_,ROW(A40)-2))))) -> #ERROR!
X41: =IF(VLOOKUP(data2!BJ41,misc!$A$8:$B$11,2,0)="normal",data2!BK41,VLOOKUP(data2!BJ41,misc!$A$8:$B$11,2,0)) -> undershift | Y41: =IF(VLOOKUP(data2!CL41,misc!$A$8:$B$11,2,0)="normal",data2!CM41,VLOOKUP(data2!CL41,misc!$A$8:$B$11,2,0)) -> uppershift | Z41: =IF(VLOOKUP(data2!DN41,misc!$A$8:$B$11,2,0)="normal",data2!DO41,VLOOKUP(data2!DN41,misc!$A$8:$B$11,2,0)) -> tight profile | AA41: =IF(ISERROR(AVERAGE(INDEX(JPM1_,ROW(A41)-2),(INDEX(JPM2_,ROW(A41)-2),(INDEX(JPM3_,ROW(A41)-2)))))=TRUE,"N/A",AVERAGE(INDEX(JPM1_,ROW(A41)-2),(INDEX(JPM2_,ROW(A41)-2),(INDEX(JPM3_,ROW(A41)-2))))) -> #ERROR!
X42: =IF(VLOOKUP(data2!BJ42,misc!$A$8:$B$11,2,0)="normal",data2!BK42,VLOOKUP(data2!BJ42,misc!$A$8:$B$11,2,0)) -> undershift | Y42: =IF(VLOOKUP(data2!CL42,misc!$A$8:$B$11,2,0)="normal",data2!CM42,VLOOKUP(data2!CL42,misc!$A$8:$B$11,2,0)) -> uppershift | Z42: =IF(VLOOKUP(data2!DN42,misc!$A$8:$B$11,2,0)="normal",data2!DO42,VLOOKUP(data2!DN42,misc!$A$8:$B$11,2,0)) -> tight profile | AA42: =IF(ISERROR(AVERAGE(INDEX(JPM1_,ROW(A42)-2),(INDEX(JPM2_,ROW(A42)-2),(INDEX(JPM3_,ROW(A42)-2)))))=TRUE,"N/A",AVERAGE(INDEX(JPM1_,ROW(A42)-2),(INDEX(JPM2_,ROW(A42)-2),(INDEX(JPM3_,ROW(A42)-2))))) -> #ERROR!
X43: =IF(VLOOKUP(data2!BJ43,misc!$A$8:$B$11,2,0)="normal",data2!BK43,VLOOKUP(data2!BJ43,misc!$A$8:$B$11,2,0)) -> undershift | Y43: =IF(VLOOKUP(data2!CL43,misc!$A$8:$B$11,2,0)="normal",data2!CM43,VLOOKUP(data2!CL43,misc!$A$8:$B$11,2,0)) -> uppershift | Z43: =IF(VLOOKUP(data2!DN43,misc!$A$8:$B$11,2,0)="normal",data2!DO43,VLOOKUP(data2!DN43,misc!$A$8:$B$11,2,0)) -> tight profile | AA43: =IF(ISERROR(AVERAGE(INDEX(JPM1_,ROW(A43)-2),(INDEX(JPM2_,ROW(A43)-2),(INDEX(JPM3_,ROW(A43)-2)))))=TRUE,"N/A",AVERAGE(INDEX(JPM1_,ROW(A43)-2),(INDEX(JPM2_,ROW(A43)-2),(INDEX(JPM3_,ROW(A43)-2))))) -> #ERROR!
X44: =IF(VLOOKUP(data2!BJ44,misc!$A$8:$B$11,2,0)="normal",data2!BK44,VLOOKUP(data2!BJ44,misc!$A$8:$B$11,2,0)) -> undershift | Y44: =IF(VLOOKUP(data2!CL44,misc!$A$8:$B$11,2,0)="normal",data2!CM44,VLOOKUP(data2!CL44,misc!$A$8:$B$11,2,0)) -> uppershift | Z44: =IF(VLOOKUP(data2!DN44,misc!$A$8:$B$11,2,0)="normal",data2!DO44,VLOOKUP(data2!DN44,misc!$A$8:$B$11,2,0)) -> tight profile | AA44: =IF(ISERROR(AVERAGE(INDEX(JPM1_,ROW(A44)-2),(INDEX(JPM2_,ROW(A44)-2),(INDEX(JPM3_,ROW(A44)-2)))))=TRUE,"N/A",AVERAGE(INDEX(JPM1_,ROW(A44)-2),(INDEX(JPM2_,ROW(A44)-2),(INDEX(JPM3_,ROW(A44)-2))))) -> #ERROR!
F45: profiling | V45: =SUM(G45:T45) -> 0 | W45: =SUM(L45:P45) -> 0 | X45: =IF(VLOOKUP(data2!BJ45,misc!$A$8:$B$11,2,0)="normal",data2!BK45,VLOOKUP(data2!BJ45,misc!$A$8:$B$11,2,0)) -> undershift | Y45: =IF(VLOOKUP(data2!CL45,misc!$A$8:$B$11,2,0)="normal",data2!CM45,VLOOKUP(data2!CL45,misc!$A$8:$B$11,2,0)) -> uppershift | Z45: =IF(VLOOKUP(data2!DN45,misc!$A$8:$B$11,2,0)="normal",data2!DO45,VLOOKUP(data2!DN45,misc!$A$8:$B$11,2,0)) -> tight profile | AA45: =IF(ISERROR(AVERAGE(INDEX(JPM1_,ROW(A45)-2),(INDEX(JPM2_,ROW(A45)-2),(INDEX(JPM3_,ROW(A45)-2)))))=TRUE,"N/A",AVERAGE(INDEX(JPM1_,ROW(A45)-2),(INDEX(JPM2_,ROW(A45)-2),(INDEX(JPM3_,ROW(A45)-2))))) -> #ERROR!
F46: profiling | V46: =SUM(G46:T46) -> 0 | W46: =SUM(L46:P46) -> 0 | X46: =IF(VLOOKUP(data2!BJ46,misc!$A$8:$B$11,2,0)="normal",data2!BK46,VLOOKUP(data2!BJ46,misc!$A$8:$B$11,2,0)) -> undershift | Y46: =IF(VLOOKUP(data2!CL46,misc!$A$8:$B$11,2,0)="normal",data2!CM46,VLOOKUP(data2!CL46,misc!$A$8:$B$11,2,0)) -> uppershift | Z46: =IF(VLOOKUP(data2!DN46,misc!$A$8:$B$11,2,0)="normal",data2!DO46,VLOOKUP(data2!DN46,misc!$A$8:$B$11,2,0)) -> tight profile | AA46: =IF(ISERROR(AVERAGE(INDEX(JPM1_,ROW(A46)-2),(INDEX(JPM2_,ROW(A46)-2),(INDEX(JPM3_,ROW(A46)-2)))))=TRUE,"N/A",AVERAGE(INDEX(JPM1_,ROW(A46)-2),(INDEX(JPM2_,ROW(A46)-2),(INDEX(JPM3_,ROW(A46)-2))))) -> #ERROR!
F47: profiling | V47: =SUM(G47:T47) -> 0 | W47: =SUM(L47:P47) -> 0 | X47: =IF(VLOOKUP(data2!BJ47,misc!$A$8:$B$11,2,0)="normal",data2!BK47,VLOOKUP(data2!BJ47,misc!$A$8:$B$11,2,0)) -> undershift | Y47: =IF(VLOOKUP(data2!CL47,misc!$A$8:$B$11,2,0)="normal",data2!CM47,VLOOKUP(data2!CL47,misc!$A$8:$B$11,2,0)) -> uppershift | Z47: =IF(VLOOKUP(data2!DN47,misc!$A$8:$B$11,2,0)="normal",data2!DO47,VLOOKUP(data2!DN47,misc!$A$8:$B$11,2,0)) -> tight profile | AA47: =IF(ISERROR(AVERAGE(INDEX(JPM1_,ROW(A47)-2),(INDEX(JPM2_,ROW(A47)-2),(INDEX(JPM3_,ROW(A47)-2)))))=TRUE,"N/A",AVERAGE(INDEX(JPM1_,ROW(A47)-2),(INDEX(JPM2_,ROW(A47)-2),(INDEX(JPM3_,ROW(A47)-2))))) -> #ERROR!
F48: profiling | V48: =SUM(G48:T48) -> 0 | W48: =SUM(L48:P48) -> 0 | X48: =IF(VLOOKUP(data2!BJ48,misc!$A$8:$B$11,2,0)="normal",data2!BK48,VLOOKUP(data2!BJ48,misc!$A$8:$B$11,2,0)) -> undershift | Y48: =IF(VLOOKUP(data2!CL48,misc!$A$8:$B$11,2,0)="normal",data2!CM48,VLOOKUP(data2!CL48,misc!$A$8:$B$11,2,0)) -> uppershift | Z48: =IF(VLOOKUP(data2!DN48,misc!$A$8:$B$11,2,0)="normal",data2!DO48,VLOOKUP(data2!DN48,misc!$A$8:$B$11,2,0)) -> tight profile | AA48: =IF(ISERROR(AVERAGE(INDEX(JPM1_,ROW(A48)-2),(INDEX(JPM2_,ROW(A48)-2),(INDEX(JPM3_,ROW(A48)-2)))))=TRUE,"N/A",AVERAGE(INDEX(JPM1_,ROW(A48)-2),(INDEX(JPM2_,ROW(A48)-2),(INDEX(JPM3_,ROW(A48)-2))))) -> #ERROR!
F49: profiling | V49: =SUM(G49:T49) -> 0 | W49: =SUM(L49:P49) -> 0 | X49: =IF(VLOOKUP(data2!BJ49,misc!$A$8:$B$11,2,0)="normal",data2!BK49,VLOOKUP(data2!BJ49,misc!$A$8:$B$11,2,0)) -> undershift | Y49: =IF(VLOOKUP(data2!CL49,misc!$A$8:$B$11,2,0)="normal",data2!CM49,VLOOKUP(data2!CL49,misc!$A$8:$B$11,2,0)) -> uppershift | Z49: =IF(VLOOKUP(data2!DN49,misc!$A$8:$B$11,2,0)="normal",data2!DO49,VLOOKUP(data2!DN49,misc!$A$8:$B$11,2,0)) -> tight profile | AA49: =IF(ISERROR(AVERAGE(INDEX(JPM1_,ROW(A49)-2),(INDEX(JPM2_,ROW(A49)-2),(INDEX(JPM3_,ROW(A49)-2)))))=TRUE,"N/A",AVERAGE(INDEX(JPM1_,ROW(A49)-2),(INDEX(JPM2_,ROW(A49)-2),(INDEX(JPM3_,ROW(A49)-2))))) -> #ERROR!
F50: profiling | V50: =SUM(G50:T50) -> 0 | W50: =SUM(L50:P50) -> 0 | X50: =IF(VLOOKUP(data2!BJ50,misc!$A$8:$B$11,2,0)="normal",data2!BK50,VLOOKUP(data2!BJ50,misc!$A$8:$B$11,2,0)) -> undershift | Y50: =IF(VLOOKUP(data2!CL50,misc!$A$8:$B$11,2,0)="normal",data2!CM50,VLOOKUP(data2!CL50,misc!$A$8:$B$11,2,0)) -> uppershift | Z50: =IF(VLOOKUP(data2!DN50,misc!$A$8:$B$11,2,0)="normal",data2!DO50,VLOOKUP(data2!DN50,misc!$A$8:$B$11,2,0)) -> tight profile | AA50: =IF(ISERROR(AVERAGE(INDEX(JPM1_,ROW(A50)-2),(INDEX(JPM2_,ROW(A50)-2),(INDEX(JPM3_,ROW(A50)-2)))))=TRUE,"N/A",AVERAGE(INDEX(JPM1_,ROW(A50)-2),(INDEX(JPM2_,ROW(A50)-2),(INDEX(JPM3_,ROW(A50)-2))))) -> #ERROR!
F51: profiling | V51: =SUM(G51:T51) -> 0 | W51: =SUM(L51:P51) -> 0 | X51: =IF(VLOOKUP(data2!BJ51,misc!$A$8:$B$11,2,0)="normal",data2!BK51,VLOOKUP(data2!BJ51,misc!$A$8:$B$11,2,0)) -> undershift | Y51: =IF(VLOOKUP(data2!CL51,misc!$A$8:$B$11,2,0)="normal",data2!CM51,VLOOKUP(data2!CL51,misc!$A$8:$B$11,2,0)) -> uppershift | Z51: =IF(VLOOKUP(data2!DN51,misc!$A$8:$B$11,2,0)="normal",data2!DO51,VLOOKUP(data2!DN51,misc!$A$8:$B$11,2,0)) -> tight profile | AA51: =IF(ISERROR(AVERAGE(INDEX(JPM1_,ROW(A51)-2),(INDEX(JPM2_,ROW(A51)-2),(INDEX(JPM3_,ROW(A51)-2)))))=TRUE,"N/A",AVERAGE(INDEX(JPM1_,ROW(A51)-2),(INDEX(JPM2_,ROW(A51)-2),(INDEX(JPM3_,ROW(A51)-2))))) -> #ERROR!
F52: profiling | V52: =SUM(G52:T52) -> 0 | W52: =SUM(L52:P52) -> 0 | X52: =IF(VLOOKUP(data2!BJ52,misc!$A$8:$B$11,2,0)="normal",data2!BK52,VLOOKUP(data2!BJ52,misc!$A$8:$B$11,2,0)) -> undershift | Y52: =IF(VLOOKUP(data2!CL52,misc!$A$8:$B$11,2,0)="normal",data2!CM52,VLOOKUP(data2!CL52,misc!$A$8:$B$11,2,0)) -> uppershift | Z52: =IF(VLOOKUP(data2!DN52,misc!$A$8:$B$11,2,0)="normal",data2!DO52,VLOOKUP(data2!DN52,misc!$A$8:$B$11,2,0)) -> tight profile | AA52: =IF(ISERROR(AVERAGE(INDEX(JPM1_,ROW(A52)-2),(INDEX(JPM2_,ROW(A52)-2),(INDEX(JPM3_,ROW(A52)-2)))))=TRUE,"N/A",AVERAGE(INDEX(JPM1_,ROW(A52)-2),(INDEX(JPM2_,ROW(A52)-2),(INDEX(JPM3_,ROW(A52)-2))))) -> #ERROR!
F53: profiling | V53: =SUM(G53:T53) -> 0 | W53: =SUM(L53:P53) -> 0 | X53: =IF(VLOOKUP(data2!BJ53,misc!$A$8:$B$11,2,0)="normal",data2!BK53,VLOOKUP(data2!BJ53,misc!$A$8:$B$11,2,0)) -> undershift | Y53: =IF(VLOOKUP(data2!CL53,misc!$A$8:$B$11,2,0)="normal",data2!CM53,VLOOKUP(data2!CL53,misc!$A$8:$B$11,2,0)) -> uppershift | Z53: =IF(VLOOKUP(data2!DN53,misc!$A$8:$B$11,2,0)="normal",data2!DO53,VLOOKUP(data2!DN53,misc!$A$8:$B$11,2,0)) -> tight profile | AA53: =IF(ISERROR(AVERAGE(INDEX(JPM1_,ROW(A53)-2),(INDEX(JPM2_,ROW(A53)-2),(INDEX(JPM3_,ROW(A53)-2)))))=TRUE,"N/A",AVERAGE(INDEX(JPM1_,ROW(A53)-2),(INDEX(JPM2_,ROW(A53)-2),(INDEX(JPM3_,ROW(A53)-2))))) -> #ERROR!
F54: profiling | V54: =SUM(G54:T54) -> 0 | W54: =SUM(L54:P54) -> 0 | X54: =IF(VLOOKUP(data2!BJ54,misc!$A$8:$B$11,2,0)="normal",data2!BK54,VLOOKUP(data2!BJ54,misc!$A$8:$B$11,2,0)) -> undershift | Y54: =IF(VLOOKUP(data2!CL54,misc!$A$8:$B$11,2,0)="normal",data2!CM54,VLOOKUP(data2!CL54,misc!$A$8:$B$11,2,0)) -> uppershift | Z54: =IF(VLOOKUP(data2!DN54,misc!$A$8:$B$11,2,0)="normal",data2!DO54,VLOOKUP(data2!DN54,misc!$A$8:$B$11,2,0)) -> tight profile | AA54: =IF(ISERROR(AVERAGE(INDEX(JPM1_,ROW(A54)-2),(INDEX(JPM2_,ROW(A54)-2),(INDEX(JPM3_,ROW(A54)-2)))))=TRUE,"N/A",AVERAGE(INDEX(JPM1_,ROW(A54)-2),(INDEX(JPM2_,ROW(A54)-2),(INDEX(JPM3_,ROW(A54)-2))))) -> #ERROR!
F55: profiling | V55: =SUM(G55:T55) -> 0 | W55: =SUM(L55:P55) -> 0 | X55: =IF(VLOOKUP(data2!BJ55,misc!$A$8:$B$11,2,0)="normal",data2!BK55,VLOOKUP(data2!BJ55,misc!$A$8:$B$11,2,0)) -> undershift | Y55: =IF(VLOOKUP(data2!CL55,misc!$A$8:$B$11,2,0)="normal",data2!CM55,VLOOKUP(data2!CL55,misc!$A$8:$B$11,2,0)) -> uppershift | Z55: =IF(VLOOKUP(data2!DN55,misc!$A$8:$B$11,2,0)="normal",data2!DO55,VLOOKUP(data2!DN55,misc!$A$8:$B$11,2,0)) -> tight profile | AA55: =IF(ISERROR(AVERAGE(INDEX(JPM1_,ROW(A55)-2),(INDEX(JPM2_,ROW(A55)-2),(INDEX(JPM3_,ROW(A55)-2)))))=TRUE,"N/A",AVERAGE(INDEX(JPM1_,ROW(A55)-2),(INDEX(JPM2_,ROW(A55)-2),(INDEX(JPM3_,ROW(A55)-2))))) -> #ERROR!
F56: profiling | V56: =SUM(G56:T56) -> 0 | W56: =SUM(L56:P56) -> 0 | X56: =IF(VLOOKUP(data2!BJ56,misc!$A$8:$B$11,2,0)="normal",data2!BK56,VLOOKUP(data2!BJ56,misc!$A$8:$B$11,2,0)) -> undershift | Y56: =IF(VLOOKUP(data2!CL56,misc!$A$8:$B$11,2,0)="normal",data2!CM56,VLOOKUP(data2!CL56,misc!$A$8:$B$11,2,0)) -> uppershift | Z56: =IF(VLOOKUP(data2!DN56,misc!$A$8:$B$11,2,0)="normal",data2!DO56,VLOOKUP(data2!DN56,misc!$A$8:$B$11,2,0)) -> tight profile | AA56: =IF(ISERROR(AVERAGE(INDEX(JPM1_,ROW(A56)-2),(INDEX(JPM2_,ROW(A56)-2),(INDEX(JPM3_,ROW(A56)-2)))))=TRUE,"N/A",AVERAGE(INDEX(JPM1_,ROW(A56)-2),(INDEX(JPM2_,ROW(A56)-2),(INDEX(JPM3_,ROW(A56)-2))))) -> #ERROR!
... F71: profiling | V71: =SUM(G71:T71) -> 0 | W71: =SUM(L71:P71) -> 0 | X71: =IF(VLOOKUP(data2!BJ71,misc!$A$8:$B$11,2,0)="normal",data2!BK71,VLOOKUP(data2!BJ71,misc!$A$8:$B$11,2,0)) -> undershift | Y71: =IF(VLOOKUP(data2!CL71,misc!$A$8:$B$11,2,0)="normal",data2!CM71,VLOOKUP(data2!CL71,misc!$A$8:$B$11,2,0)) -> uppershift | Z71: =IF(VLOOKUP(data2!DN71,misc!$A$8:$B$11,2,0)="normal",data2!DO71,VLOOKUP(data2!DN71,misc!$A$8:$B$11,2,0)) -> tight profile | AA71: =IF(ISERROR(AVERAGE(INDEX(JPM1_,ROW(A71)-2),(INDEX(JPM2_,ROW(A71)-2),(INDEX(JPM3_,ROW(A71)-2)))))=TRUE,"N/A",AVERAGE(INDEX(JPM1_,ROW(A71)-2),(INDEX(JPM2_,ROW(A71)-2),(INDEX(JPM3_,ROW(A71)-2))))) -> #ERROR!
F72: profiling | V72: =SUM(G72:K72) -> 0 | W72: =SUM(L72:P72) -> 0 | X72: =IF(VLOOKUP(data2!BJ72,misc!$A$8:$B$11,2,0)="normal",data2!BK72,VLOOKUP(data2!BJ72,misc!$A$8:$B$11,2,0)) -> undershift | Y72: =IF(VLOOKUP(data2!CL72,misc!$A$8:$B$11,2,0)="normal",data2!CM72,VLOOKUP(data2!CL72,misc!$A$8:$B$11,2,0)) -> uppershift | Z72: =IF(VLOOKUP(data2!DN72,misc!$A$8:$B$11,2,0)="normal",data2!DO72,VLOOKUP(data2!DN72,misc!$A$8:$B$11,2,0)) -> tight profile | AA72: =IF(ISERROR(AVERAGE(INDEX(JPM1_,ROW(A72)-2),(INDEX(JPM2_,ROW(A72)-2),(INDEX(JPM3_,ROW(A72)-2)))))=TRUE,"N/A",AVERAGE(INDEX(JPM1_,ROW(A72)-2),(INDEX(JPM2_,ROW(A72)-2),(INDEX(JPM3_,ROW(A72)-2))))) -> #ERROR!
F73: profiling | V73: =SUM(G73:K73) -> 0 | W73: =SUM(L73:P73) -> 0 | X73: =IF(VLOOKUP(data2!BJ73,misc!$A$8:$B$11,2,0)="normal",data2!BK73,VLOOKUP(data2!BJ73,misc!$A$8:$B$11,2,0)) -> undershift | Y73: =IF(VLOOKUP(data2!CL73,misc!$A$8:$B$11,2,0)="normal",data2!CM73,VLOOKUP(data2!CL73,misc!$A$8:$B$11,2,0)) -> uppershift | Z73: =IF(VLOOKUP(data2!DN73,misc!$A$8:$B$11,2,0)="normal",data2!DO73,VLOOKUP(data2!DN73,misc!$A$8:$B$11,2,0)) -> tight profile | AA73: =IF(ISERROR(AVERAGE(INDEX(JPM1_,ROW(A73)-2),(INDEX(JPM2_,ROW(A73)-2),(INDEX(JPM3_,ROW(A73)-2)))))=TRUE,"N/A",AVERAGE(INDEX(JPM1_,ROW(A73)-2),(INDEX(JPM2_,ROW(A73)-2),(INDEX(JPM3_,ROW(A73)-2))))) -> #ERROR!
...

Sheet data2
A1: {=data!A1:W2} | B1: Jenis | D1: Tanggal | G1: Most | L1: Least | Q1: Change | V1: Cek | X1: tentukan koordinat grafiknya | Y1: D | Z1: I | AA1: S | AB1: C | AC1: D | AD1: I | AE1: S | AF1: C | AG1: D | AH1: I | AI1: S | AJ1: C | AK1: cari grafik 1 tertinggi | AP1: rank grafik 1 | AU1: profil graf 1 | AZ1: profil dom 1 | BE1: profil res 1 | BJ1: profil final 1 | BM1: cari grafik 2 tertinggi | BR1: rank grafik 2 | BW1: profil graf 2 | CB1: profil dom 2 | CG1: profil res 2 | CL1: profil final 2 | CO1: cari grafik 3 tertinggi | CT1: rank grafik 3 | CY1: profil graf 3 | DD1: profil dom 3 | DI1: profil res 3 | DN1: profil final 3 | DR1: buat individual jpm | ED1: pilihan job profile | EH1: compare job profile
A2: Nama | B2: Kelamin | C2: Nomor | D2: Tes | E2: Posisi | F2: Tujuan | G2: D | H2: I | I2: S | J2: C | K2: B | L2: D | M2: I | N2: S | O2: C | P2: B | Q2: D | R2: I | S2: S | T2: C | U2: B | V2: M | W2: L | Y2: PG1MD | Z2: PG1MI | AA2: PG1MS | AB2: PG1MC | AC2: PG2LD | AD2: PG2LI | AE2: PG2LS | AF2: PG2LC | AG2: PG3CD | AH2: PG3CI | AI2: PG3CS | AJ2: PG3CC | AL2: 1 | AM2: 2 | AN2: 3 | AO2: 4 | AQ2: 1 | AR2: 2 | AS2: 3 | AT2: 4 | AV2: 1 | AW2: 2 | AX2: 3 | AY2: 4 | BA2: 1 | BB2: 2 | BC2: 3 | BD2: 4 | BF2: 1 | BG2: 2 | BH2: 3 | BI2: 4 | BJ2: cek1 | BK2: prof1 | BN2: 1 | BO2: 2 | BP2: 3 | BQ2: 4 | BS2: 1 | BT2: 2 | BU2: 3 | BV2: 4 | BX2: 1 | BY2: 2 | BZ2: 3 | CA2: 4 | CC2: 1 | CD2: 2 | CE2: 3 | CF2: 4 | CH2: 1 | CI2: 2 | CJ2: 3 | CK2: 4 | CL2: cek2 | CM2: prof2 | CP2: 1 | CQ2: 2 | CR2: 3 | CS2: 4 | CU2: 1 | CV2: 2 | CW2: 3 | CX2: 4 | CZ2: 1 | DA2: 2 | DB2: 3 | DC2: 4 | DE2: 1 | DF2: 2 | DG2: 3 | DH2: 4 | DJ2: 1 | DK2: 2 | DL2: 3 | DM2: 4 | DN2: cek3 | DO2: prof3 | DP2: CEKGRAF | DQ2: unique | DR2: D1ijpm | DS2: I1ijpm | DT2: S1ijpm | DU2: C1ijpm | DV2: D2ijpm | DW2: I2ijpm | DX2: S2ijpm | DY2: C2ijpm | DZ2: D3ijpm | EA2: I3ijpm | EB2: S3ijpm | EC2: C3ijpm | ED2: JD | EE2: JI | EF2: JS | EG2: JC | EH2: c1D | EI2: c1I | EJ2: c1S | EK2: c1C | EL2: cJPM1 | EM2: JPM1 | EN2: c2D | EO2: c2I | EP2: c2S | EQ2: c2C | ER2: cJPM2 | ES2: JPM2 | ET2: c3D | EU2: c3I | EV2: c3S | EW2: c3C | EX2: cJPM3 | EY2: JPM3
A3: =data!A3 -> Andre Setiawan | B3: =data!B3 -> Pria | C3: =data!C3 | D3: =data!D3 -> 44291 | E3: =data!E3 | F3: =data!F3 -> profiling | G3: =data!G3 -> 2 | H3: =data!H3 -> 0 | ... W3: =data!W3 -> 24 | Y3: =VLOOKUP(G3,tableD1,2,0) -> 9 | Z3: =VLOOKUP(H3,tableI1,2,0) -> 3 | AA3: =VLOOKUP(I3,table1S,2,0) -> 15 | AB3: =VLOOKUP(J3,table1C,2,0) -> 28 | AC3: =VLOOKUP(L3,table2D,2,0) -> 16 | AD3: =VLOOKUP(M3,table2I,2,0) -> 9 | AE3: =VLOOKUP(N3,table2S,2,0) -> 24 | AF3: =VLOOKUP(O3,table2C,2,0) -> 31 | AG3: =VLOOKUP(Q3,table3D,2,0) -> 14 | AH3: =VLOOKUP(R3,table3I,2,0) -> 7 | AI3: =VLOOKUP(S3,table3S,2,0) -> 19 | AJ3: =VLOOKUP(T3,table3C,2,0) -> 30 | AL3: =VALUE(Y3&AL$2) -> 91 | AM3: =VALUE(Z3&AM$2) -> 32 | AN3: =VALUE(AA3&AN$2) -> 153 | AO3: =VALUE(AB3&AO$2) -> 284 | AQ3: =LARGE($AL3:$AO3,AQ$2) -> 284 | AR3: =LARGE($AL3:$AO3,AR$2) -> 153 | AS3: =LARGE($AL3:$AO3,AS$2) -> 91 | AT3: =LARGE($AL3:$AO3,AT$2) -> 32 | AV3: =VLOOKUP(VALUE(RIGHT(AQ3,1)),misc!$A$2:$B$5,2,0) -> C | AW3: =VLOOKUP(VALUE(RIGHT(AR3,1)),misc!$A$2:$B$5,2,0) -> S | AX3: =VLOOKUP(VALUE(RIGHT(AS3,1)),misc!$A$2:$B$5,2,0) -> D | AY3: =VLOOKUP(VALUE(RIGHT(AT3,1)),misc!$A$2:$B$5,2,0) -> I | BA3: =IF(VALUE(AQ3)>=170,AV3,"") -> C | BB3: =IF(VALUE(AR3)>=170,AW3,"") | BC3: =IF(VALUE(AS3)>=170,AX3,"") | BD3: =IF(VALUE(AT3)>=170,AY3,"") | BF3: =IF(VALUE(AQ3)<170,AV3,"") | BG3: =IF(VALUE(AR3)<170,AW3,"") -> S | BH3: =IF(VALUE(AS3)<170,AX3,"") -> D | BI3: =IF(VALUE(AT3)<170,AY3,"") -> I | BJ3: =IF(AND(Y3<17,Z3<17,AA3<17,AB3<17),1,IF(AND(Y3>=17,Z3>=17,AA3>=17,AB3>=17),2,IF(AND(Y3>12,Y3<21,Z3>12,Z3<21,AA3>12,AA3<21,AB3>12,AB3<21),3,4))) -> 4 | BK3: =TRIM(BA3&BB3&BC3&BD3) -> C | BN3: =VALUE(AC3&BN$2) -> 161 | BO3: =VALUE(AD3&BO$2) -> 92 | BP3: =VALUE(AE3&BP$2) -> 243 | BQ3: =VALUE(AF3&BQ$2) -> 314 | BS3: =LARGE($BN3:$BQ3,BS$2) -> 314 | BT3: =LARGE($BN3:$BQ3,BT$2) -> 243 | BU3: =LARGE($BN3:$BQ3,BU$2) -> 161 | BV3: =LARGE($BN3:$BQ3,BV$2) -> 92 | BX3: =VLOOKUP(VALUE(RIGHT(BS3,1)),misc!$A$2:$B$5,2,0) -> C | BY3: =VLOOKUP(VALUE(RIGHT(BT3,1)),misc!$A$2:$B$5,2,0) -> S | BZ3: =VLOOKUP(VALUE(RIGHT(BU3,1)),misc!$A$2:$B$5,2,0) -> D | CA3: =VLOOKUP(VALUE(RIGHT(BV3,1)),misc!$A$2:$B$5,2,0) -> I | CC3: =IF(VALUE(BS3)>=170,BX3,"") -> C | CD3: =IF(VALUE(BT3)>=170,BY3,"") -> S | CE3: =IF(VALUE(BU3)>=170,BZ3,"") | CF3: =IF(VALUE(BV3)>=170,CA3,"") | CH3: =IF(VALUE(BS3)<170,BX3,"") | CI3: =IF(VALUE(BT3)<170,BY3,"") | CJ3: =IF(VALUE(BU3)<170,BZ3,"") -> D | CK3: =IF(VALUE(BV3)<170,CA3,"") -> I | CL3: =IF(AND(AC3<17,AD3<17,AE3<17,AF3<17),1,IF(AND(AC3>=17,AD3>=17,AE3>=17,AF3>=17),2,IF(AND(AC3>12,AC3<21,AD3>12,AD3<21,AE3>12,AE3<21,AF3>12,AF3<21),3,4))) -> 4 | CM3: =TRIM(CC3&CD3&CE3&CF3) -> CS | CP3: =VALUE(AG3&CP$2) -> 141 | CQ3: =VALUE(AH3&CQ$2) -> 72 | CR3: =VALUE(AI3&CR$2) -> 193 | CS3: =VALUE(AJ3&CS$2) -> 304 | CU3: =LARGE($CP3:$CS3,CU$2) -> 304 | CV3: =LARGE($CP3:$CS3,CV$2) -> 193 | CW3: =LARGE($CP3:$CS3,CW$2) -> 141 | CX3: =LARGE($CP3:$CS3,CX$2) -> 72 | CZ3: =VLOOKUP(VALUE(RIGHT(CU3,1)),misc!$A$2:$B$5,2,0) -> C | DA3: =VLOOKUP(VALUE(RIGHT(CV3,1)),misc!$A$2:$B$5,2,0) -> S | DB3: =VLOOKUP(VALUE(RIGHT(CW3,1)),misc!$A$2:$B$5,2,0) -> D | DC3: =VLOOKUP(VALUE(RIGHT(CX3,1)),misc!$A$2:$B$5,2,0) -> I | DE3: =IF(VALUE(CU3)>=170,CZ3,"") -> C | DF3: =IF(VALUE(CV3)>=170,DA3,"") -> S | DG3: =IF(VALUE(CW3)>=170,DB3,"") | DH3: =IF(VALUE(CX3)>=170,DC3,"") | DJ3: =IF(VALUE(CU3)<170,CZ3,"") | DK3: =IF(VALUE(CV3)<170,DA3,"") | DL3: =IF(VALUE(CW3)<170,DB3,"") -> D | DM3: =IF(VALUE(CX3)<170,DC3,"") -> I | DN3: =IF(AND(AG3<17,AH3<17,AI3<17,AJ3<17),1,IF(AND(AG3>=17,AH3>=17,AI3>=17,AJ3>=17),2,IF(AND(AG3>12,AG3<21,AH3>12,AH3<21,AI3>12,AI3<21,AJ3>12,AJ3<21),3,4))) -> 4 | DO3: =TRIM(DE3&DF3&DG3&DH3) -> CS | DP3: =BJ3&CL3&DN3 -> 444 | DQ3: =A3&G3&H3&I3&J3&L3&M3&N3&O3 -> Andre Setiawan204106731 | DR3: =VLOOKUP(G3,tableD1,3,0) -> 3 | DS3: =VLOOKUP(H3,tableI1,3,0) -> 1 | DT3: =VLOOKUP(I3,table1S,3,0) -> 4 | DU3: =VLOOKUP(J3,table1C,3,0) -> 8 | DV3: =VLOOKUP(L3,table2D,3,0) -> 4 | DW3: =VLOOKUP(M3,table2I,3,0) -> 3 | DX3: =VLOOKUP(N3,table2S,3,0) -> 6 | DY3: =VLOOKUP(O3,table2C,3,0) -> 8 | DZ3: =VLOOKUP(Q3,table3D,3,0) -> 4 | EA3: =VLOOKUP(R3,table3I,3,0) -> 2 | EB3: =VLOOKUP(S3,table3S,3,0) -> 5 | EC3: =VLOOKUP(T3,table3C,3,0) -> 8 | ED3: {=VLOOKUP(INDEX(JD,data!$AA$1),key!$J$3:$L$27,3,0)} -> 6 | EE3: {=VLOOKUP(INDEX(JI,data!$AA$1),key!$J$3:$L$27,3,0)} -> 4 | EF3: {=VLOOKUP(INDEX(JS,data!$AA$1),key!$J$3:$L$27,3,0)} -> 4 | EG3: {=VLOOKUP(INDEX(JC,data!$AA$1),key!$J$3:$L$27,3,0)} -> 7 | EH3: =VLOOKUP(DR3,tabel_jpm,ED3+1,0) -> 16 | EI3: =VLOOKUP(DS3,tabel_jpm,EE3+1,0) -> 16 | EJ3: =VLOOKUP(DT3,tabel_jpm,EF3+1,0) -> 28 | EK3: =VLOOKUP(DU3,tabel_jpm,EG3+1,0) -> 24 | EL3: =IF(B3="Pria",VLOOKUP(AVERAGE(EH3:EK3),agreement_p,4),VLOOKUP(AVERAGE(EH3:EK3),agreement_w,4)) -> 62 | EM3: =IF(DP3<>"444","N/A",EL3) -> 62 | EN3: =VLOOKUP(DV3,tabel_jpm,ED3+1,0) -> 20 | EO3: =VLOOKUP(DW3,tabel_jpm,EE3+1,0) -> 24 | EP3: =VLOOKUP(DX3,tabel_jpm,EF3+1,0) -> 20 | EQ3: =VLOOKUP(DY3,tabel_jpm,EG3+1,0) -> 24 | ER3: =IF(B3="Pria",VLOOKUP(AVERAGE(EN3:EQ3),agreement_p,4),VLOOKUP(AVERAGE(EN3:EQ3),agreement_w,4)) -> 72 | ES3: =IF(DP3<>"444","N/A",ER3) -> 72 | ET3: =VLOOKUP(DZ3,tabel_jpm,ED3+1,0) -> 20 | EU3: =VLOOKUP(EA3,tabel_jpm,EE3+1,0) -> 20 | EV3: =VLOOKUP(EB3,tabel_jpm,EF3+1,0) -> 24 | EW3: =VLOOKUP(EC3,tabel_jpm,EG3+1,0) -> 24 | EX3: =IF(B3="Pria",VLOOKUP(AVERAGE(ET3:EW3),agreement_p,4),VLOOKUP(AVERAGE(ET3:EW3),agreement_w,4)) -> 72 | EY3: =IF(DP3<>"444","N/A",EX3) -> 72
A4: =data!A4 -> Helmi Kurniawan | B4: =data!B4 -> Pria | C4: =data!C4 | D4: =data!D4 | E4: =data!E4 | F4: =data!F4 -> profiling | G4: =data!G4 -> 3 | H4: =data!H4 -> 3 | ... W4: =data!W4 -> 24 | Y4: =VLOOKUP(G4,tableD1,2,0) -> 11 | Z4: =VLOOKUP(H4,tableI1,2,0) -> 15 | AA4: =VLOOKUP(I4,table1S,2,0) -> 22 | AB4: =VLOOKUP(J4,table1C,2,0) -> 18 | AC4: =VLOOKUP(L4,table2D,2,0) -> 15 | AD4: =VLOOKUP(M4,table2I,2,0) -> 18 | AE4: =VLOOKUP(N4,table2S,2,0) -> 28 | AF4: =VLOOKUP(O4,table2C,2,0) -> 18 | AG4: =VLOOKUP(Q4,table3D,2,0) -> 14 | AH4: =VLOOKUP(R4,table3I,2,0) -> 16 | AI4: =VLOOKUP(S4,table3S,2,0) -> 24 | AJ4: =VLOOKUP(T4,table3C,2,0) -> 18 | AL4: =VALUE(Y4&AL$2) -> 111 | AM4: =VALUE(Z4&AM$2) -> 152 | AN4: =VALUE(AA4&AN$2) -> 223 | AO4: =VALUE(AB4&AO$2) -> 184 | AQ4: =LARGE($AL4:$AO4,AQ$2) -> 223 | AR4: =LARGE($AL4:$AO4,AR$2) -> 184 | AS4: =LARGE($AL4:$AO4,AS$2) -> 152 | AT4: =LARGE($AL4:$AO4,AT$2) -> 111 | AV4: =VLOOKUP(VALUE(RIGHT(AQ4,1)),misc!$A$2:$B$5,2,0) -> S | AW4: =VLOOKUP(VALUE(RIGHT(AR4,1)),misc!$A$2:$B$5,2,0) -> C | AX4: =VLOOKUP(VALUE(RIGHT(AS4,1)),misc!$A$2:$B$5,2,0) -> I | AY4: =VLOOKUP(VALUE(RIGHT(AT4,1)),misc!$A$2:$B$5,2,0) -> D | BA4: =IF(VALUE(AQ4)>=170,AV4,"") -> S | BB4: =IF(VALUE(AR4)>=170,AW4,"") -> C | BC4: =IF(VALUE(AS4)>=170,AX4,"") | BD4: =IF(VALUE(AT4)>=170,AY4,"") | BF4: =IF(VALUE(AQ4)<170,AV4,"") | BG4: =IF(VALUE(AR4)<170,AW4,"") | BH4: =IF(VALUE(AS4)<170,AX4,"") -> I | BI4: =IF(VALUE(AT4)<170,AY4,"") -> D | BJ4: =IF(AND(Y4<17,Z4<17,AA4<17,AB4<17),1,IF(AND(Y4>=17,Z4>=17,AA4>=17,AB4>=17),2,IF(AND(Y4>12,Y4<21,Z4>12,Z4<21,AA4>12,AA4<21,AB4>12,AB4<21),3,4))) -> 4 | BK4: =TRIM(BA4&BB4&BC4&BD4) -> SC | BN4: =VALUE(AC4&BN$2) -> 151 | BO4: =VALUE(AD4&BO$2) -> 182 | BP4: =VALUE(AE4&BP$2) -> 283 | BQ4: =VALUE(AF4&BQ$2) -> 184 | BS4: =LARGE($BN4:$BQ4,BS$2) -> 283 | BT4: =LARGE($BN4:$BQ4,BT$2) -> 184 | BU4: =LARGE($BN4:$BQ4,BU$2) -> 182 | BV4: =LARGE($BN4:$BQ4,BV$2) -> 151 | BX4: =VLOOKUP(VALUE(RIGHT(BS4,1)),misc!$A$2:$B$5,2,0) -> S | BY4: =VLOOKUP(VALUE(RIGHT(BT4,1)),misc!$A$2:$B$5,2,0) -> C | BZ4: =VLOOKUP(VALUE(RIGHT(BU4,1)),misc!$A$2:$B$5,2,0) -> I | CA4: =VLOOKUP(VALUE(RIGHT(BV4,1)),misc!$A$2:$B$5,2,0) -> D | CC4: =IF(VALUE(BS4)>=170,BX4,"") -> S | CD4: =IF(VALUE(BT4)>=170,BY4,"") -> C | CE4: =IF(VALUE(BU4)>=170,BZ4,"") -> I | CF4: =IF(VALUE(BV4)>=170,CA4,"") | CH4: =IF(VALUE(BS4)<170,BX4,"") | CI4: =IF(VALUE(BT4)<170,BY4,"") | CJ4: =IF(VALUE(BU4)<170,BZ4,"") | CK4: =IF(VALUE(BV4)<170,CA4,"") -> D | CL4: =IF(AND(AC4<17,AD4<17,AE4<17,AF4<17),1,IF(AND(AC4>=17,AD4>=17,AE4>=17,AF4>=17),2,IF(AND(AC4>12,AC4<21,AD4>12,AD4<21,AE4>12,AE4<21,AF4>12,AF4<21),3,4))) -> 4 | CM4: =TRIM(CC4&CD4&CE4&CF4) -> SCI | CP4: =VALUE(AG4&CP$2) -> 141 | CQ4: =VALUE(AH4&CQ$2) -> 162 | CR4: =VALUE(AI4&CR$2) -> 243 | CS4: =VALUE(AJ4&CS$2) -> 184 | CU4: =LARGE($CP4:$CS4,CU$2) -> 243 | CV4: =LARGE($CP4:$CS4,CV$2) -> 184 | CW4: =LARGE($CP4:$CS4,CW$2) -> 162 | CX4: =LARGE($CP4:$CS4,CX$2) -> 141 | CZ4: =VLOOKUP(VALUE(RIGHT(CU4,1)),misc!$A$2:$B$5,2,0) -> S | DA4: =VLOOKUP(VALUE(RIGHT(CV4,1)),misc!$A$2:$B$5,2,0) -> C | DB4: =VLOOKUP(VALUE(RIGHT(CW4,1)),misc!$A$2:$B$5,2,0) -> I | DC4: =VLOOKUP(VALUE(RIGHT(CX4,1)),misc!$A$2:$B$5,2,0) -> D | DE4: =IF(VALUE(CU4)>=170,CZ4,"") -> S | DF4: =IF(VALUE(CV4)>=170,DA4,"") -> C | DG4: =IF(VALUE(CW4)>=170,DB4,"") | DH4: =IF(VALUE(CX4)>=170,DC4,"") | DJ4: =IF(VALUE(CU4)<170,CZ4,"") | DK4: =IF(VALUE(CV4)<170,DA4,"") | DL4: =IF(VALUE(CW4)<170,DB4,"") -> I | DM4: =IF(VALUE(CX4)<170,DC4,"") -> D | DN4: =IF(AND(AG4<17,AH4<17,AI4<17,AJ4<17),1,IF(AND(AG4>=17,AH4>=17,AI4>=17,AJ4>=17),2,IF(AND(AG4>12,AG4<21,AH4>12,AH4<21,AI4>12,AI4<21,AJ4>12,AJ4<21),3,4))) -> 4 | DO4: =TRIM(DE4&DF4&DG4&DH4) -> SC | DP4: =BJ4&CL4&DN4 -> 444 | DQ4: =A4&G4&H4&I4&J4&L4&M4&N4&O4 -> Helmi Kurniawan33747426 | DR4: =VLOOKUP(G4,tableD1,3,0) -> 3 | DS4: =VLOOKUP(H4,tableI1,3,0) -> 4 | DT4: =VLOOKUP(I4,table1S,3,0) -> 6 | DU4: =VLOOKUP(J4,table1C,3,0) -> 5 | DV4: =VLOOKUP(L4,table2D,3,0) -> 4 | DW4: =VLOOKUP(M4,table2I,3,0) -> 5 | DX4: =VLOOKUP(N4,table2S,3,0) -> 7 | DY4: =VLOOKUP(O4,table2C,3,0) -> 5 | DZ4: =VLOOKUP(Q4,table3D,3,0) -> 4 | EA4: =VLOOKUP(R4,table3I,3,0) -> 4 | EB4: =VLOOKUP(S4,table3S,3,0) -> 6 | EC4: =VLOOKUP(T4,table3C,3,0) -> 5 | ED4: {=VLOOKUP(INDEX(JD,data!$AA$1),key!$J$3:$L$27,3,0)} -> 6 | EE4: {=VLOOKUP(INDEX(JI,data!$AA$1),key!$J$3:$L$27,3,0)} -> 4 | EF4: {=VLOOKUP(INDEX(JS,data!$AA$1),key!$J$3:$L$27,3,0)} -> 4 | EG4: {=VLOOKUP(INDEX(JC,data!$AA$1),key!$J$3:$L$27,3,0)} -> 7 | EH4: =VLOOKUP(DR4,tabel_jpm,ED4+1,0) -> 16 | EI4: =VLOOKUP(DS4,tabel_jpm,EE4+1,0) -> 28 | EJ4: =VLOOKUP(DT4,tabel_jpm,EF4+1,0) -> 20 | EK4: =VLOOKUP(DU4,tabel_jpm,EG4+1,0) -> 20 | EL4: =IF(B4="Pria",VLOOKUP(AVERAGE(EH4:EK4),agreement_p,4),VLOOKUP(AVERAGE(EH4:EK4),agreement_w,4)) -> 62 | EM4: =IF(DP4<>"444","N/A",EL4) -> 62 | EN4: =VLOOKUP(DV4,tabel_jpm,ED4+1,0) -> 20 | EO4: =VLOOKUP(DW4,tabel_jpm,EE4+1,0) -> 24 | EP4: =VLOOKUP(DX4,tabel_jpm,EF4+1,0) -> 16 | EQ4: =VLOOKUP(DY4,tabel_jpm,EG4+1,0) -> 20 | ER4: =IF(B4="Pria",VLOOKUP(AVERAGE(EN4:EQ4),agreement_p,4),VLOOKUP(AVERAGE(EN4:EQ4),agreement_w,4)) -> 59 | ES4: =IF(DP4<>"444","N/A",ER4) -> 59 | ET4: =VLOOKUP(DZ4,tabel_jpm,ED4+1,0) -> 20 | EU4: =VLOOKUP(EA4,tabel_jpm,EE4+1,0) -> 28 | EV4: =VLOOKUP(EB4,tabel_jpm,EF4+1,0) -> 20 | EW4: =VLOOKUP(EC4,tabel_jpm,EG4+1,0) -> 20 | EX4: =IF(B4="Pria",VLOOKUP(AVERAGE(ET4:EW4),agreement_p,4),VLOOKUP(AVERAGE(ET4:EW4),agreement_w,4)) -> 72 | EY4: =IF(DP4<>"444","N/A",EX4) -> 72
A5: =data!A5 -> Indah Nopitasari | B5: =data!B5 -> Wanita | C5: =data!C5 | D5: =data!D5 | E5: =data!E5 | F5: =data!F5 -> profiling | G5: =data!G5 -> 0 | H5: =data!H5 -> 1 | ... W5: =data!W5 -> 24 | Y5: =VLOOKUP(G5,tableD1,2,0) -> 4 | Z5: =VLOOKUP(H5,tableI1,2,0) -> 7 | AA5: =VLOOKUP(I5,table1S,2,0) -> 26 | AB5: =VLOOKUP(J5,table1C,2,0) -> 18 | AC5: =VLOOKUP(L5,table2D,2,0) -> 3 | AD5: =VLOOKUP(M5,table2I,2,0) -> 22 | AE5: =VLOOKUP(N5,table2S,2,0) -> 32 | AF5: =VLOOKUP(O5,table2C,2,0) -> 28 | AG5: =VLOOKUP(Q5,table3D,2,0) -> 3 | AH5: =VLOOKUP(R5,table3I,2,0) -> 14 | AI5: =VLOOKUP(S5,table3S,2,0) -> 30 | AJ5: =VLOOKUP(T5,table3C,2,0) -> 24 | AL5: =VALUE(Y5&AL$2) -> 41 | AM5: =VALUE(Z5&AM$2) -> 72 | AN5: =VALUE(AA5&AN$2) -> 263 | AO5: =VALUE(AB5&AO$2) -> 184 | AQ5: =LARGE($AL5:$AO5,AQ$2) -> 263 | AR5: =LARGE($AL5:$AO5,AR$2) -> 184 | AS5: =LARGE($AL5:$AO5,AS$2) -> 72 | AT5: =LARGE($AL5:$AO5,AT$2) -> 41 | AV5: =VLOOKUP(VALUE(RIGHT(AQ5,1)),misc!$A$2:$B$5,2,0) -> S | AW5: =VLOOKUP(VALUE(RIGHT(AR5,1)),misc!$A$2:$B$5,2,0) -> C | AX5: =VLOOKUP(VALUE(RIGHT(AS5,1)),misc!$A$2:$B$5,2,0) -> I | AY5: =VLOOKUP(VALUE(RIGHT(AT5,1)),misc!$A$2:$B$5,2,0) -> D | BA5: =IF(VALUE(AQ5)>=170,AV5,"") -> S | BB5: =IF(VALUE(AR5)>=170,AW5,"") -> C | BC5: =IF(VALUE(AS5)>=170,AX5,"") | BD5: =IF(VALUE(AT5)>=170,AY5,"") | BF5: =IF(VALUE(AQ5)<170,AV5,"") | BG5: =IF(VALUE(AR5)<170,AW5,"") | BH5: =IF(VALUE(AS5)<170,AX5,"") -> I | BI5: =IF(VALUE(AT5)<170,AY5,"") -> D | BJ5: =IF(AND(Y5<17,Z5<17,AA5<17,AB5<17),1,IF(AND(Y5>=17,Z5>=17,AA5>=17,AB5>=17),2,IF(AND(Y5>12,Y5<21,Z5>12,Z5<21,AA5>12,AA5<21,AB5>12,AB5<21),3,4))) -> 4 | BK5: =TRIM(BA5&BB5&BC5&BD5) -> SC | BN5: =VALUE(AC5&BN$2) -> 31 | BO5: =VALUE(AD5&BO$2) -> 222 | BP5: =VALUE(AE5&BP$2) -> 323 | BQ5: =VALUE(AF5&BQ$2) -> 284 | BS5: =LARGE($BN5:$BQ5,BS$2) -> 323 | BT5: =LARGE($BN5:$BQ5,BT$2) -> 284 | BU5: =LARGE($BN5:$BQ5,BU$2) -> 222 | BV5: =LARGE($BN5:$BQ5,BV$2) -> 31 | BX5: =VLOOKUP(VALUE(RIGHT(BS5,1)),misc!$A$2:$B$5,2,0) -> S | BY5: =VLOOKUP(VALUE(RIGHT(BT5,1)),misc!$A$2:$B$5,2,0) -> C | BZ5: =VLOOKUP(VALUE(RIGHT(BU5,1)),misc!$A$2:$B$5,2,0) -> I | CA5: =VLOOKUP(VALUE(RIGHT(BV5,1)),misc!$A$2:$B$5,2,0) -> D | CC5: =IF(VALUE(BS5)>=170,BX5,"") -> S | CD5: =IF(VALUE(BT5)>=170,BY5,"") -> C | CE5: =IF(VALUE(BU5)>=170,BZ5,"") -> I | CF5: =IF(VALUE(BV5)>=170,CA5,"") | CH5: =IF(VALUE(BS5)<170,BX5,"") | CI5: =IF(VALUE(BT5)<170,BY5,"") | CJ5: =IF(VALUE(BU5)<170,BZ5,"") | CK5: =IF(VALUE(BV5)<170,CA5,"") -> D | CL5: =IF(AND(AC5<17,AD5<17,AE5<17,AF5<17),1,IF(AND(AC5>=17,AD5>=17,AE5>=17,AF5>=17),2,IF(AND(AC5>12,AC5<21,AD5>12,AD5<21,AE5>12,AE5<21,AF5>12,AF5<21),3,4))) -> 4 | CM5: =TRIM(CC5&CD5&CE5&CF5) -> SCI | CP5: =VALUE(AG5&CP$2) -> 31 | CQ5: =VALUE(AH5&CQ$2) -> 142 | CR5: =VALUE(AI5&CR$2) -> 303 | CS5: =VALUE(AJ5&CS$2) -> 244 | CU5: =LARGE($CP5:$CS5,CU$2) -> 303 | CV5: =LARGE($CP5:$CS5,CV$2) -> 244 | CW5: =LARGE($CP5:$CS5,CW$2) -> 142 | CX5: =LARGE($CP5:$CS5,CX$2) -> 31 | CZ5: =VLOOKUP(VALUE(RIGHT(CU5,1)),misc!$A$2:$B$5,2,0) -> S | DA5: =VLOOKUP(VALUE(RIGHT(CV5,1)),misc!$A$2:$B$5,2,0) -> C | DB5: =VLOOKUP(VALUE(RIGHT(CW5,1)),misc!$A$2:$B$5,2,0) -> I | DC5: =VLOOKUP(VALUE(RIGHT(CX5,1)),misc!$A$2:$B$5,2,0) -> D | DE5: =IF(VALUE(CU5)>=170,CZ5,"") -> S | DF5: =IF(VALUE(CV5)>=170,DA5,"") -> C | DG5: =IF(VALUE(CW5)>=170,DB5,"") | DH5: =IF(VALUE(CX5)>=170,DC5,"") | DJ5: =IF(VALUE(CU5)<170,CZ5,"") | DK5: =IF(VALUE(CV5)<170,DA5,"") | DL5: =IF(VALUE(CW5)<170,DB5,"") -> I | DM5: =IF(VALUE(CX5)<170,DC5,"") -> D | DN5: =IF(AND(AG5<17,AH5<17,AI5<17,AJ5<17),1,IF(AND(AG5>=17,AH5>=17,AI5>=17,AJ5>=17),2,IF(AND(AG5>12,AG5<21,AH5>12,AH5<21,AI5>12,AI5<21,AJ5>12,AJ5<21),3,4))) -> 4 | DO5: =TRIM(DE5&DF5&DG5&DH5) -> SC | DP5: =BJ5&CL5&DN5 -> 444 | DQ5: =A5&G5&H5&I5&J5&L5&M5&N5&O5 -> Indah Nopitasari0111416302 | DR5: =VLOOKUP(G5,tableD1,3,0) -> 1 | DS5: =VLOOKUP(H5,tableI1,3,0) -> 2 | DT5: =VLOOKUP(I5,table1S,3,0) -> 7 | DU5: =VLOOKUP(J5,table1C,3,0) -> 5 | DV5: =VLOOKUP(L5,table2D,3,0) -> 1 | DW5: =VLOOKUP(M5,table2I,3,0) -> 6 | DX5: =VLOOKUP(N5,table2S,3,0) -> 8 | DY5: =VLOOKUP(O5,table2C,3,0) -> 7 | DZ5: =VLOOKUP(Q5,table3D,3,0) -> 1 | EA5: =VLOOKUP(R5,table3I,3,0) -> 4 | EB5: =VLOOKUP(S5,table3S,3,0) -> 8 | EC5: =VLOOKUP(T5,table3C,3,0) -> 6 | ED5: {=VLOOKUP(INDEX(JD,data!$AA$1),key!$J$3:$L$27,3,0)} -> 6 | EE5: {=VLOOKUP(INDEX(JI,data!$AA$1),key!$J$3:$L$27,3,0)} -> 4 | EF5: {=VLOOKUP(INDEX(JS,data!$AA$1),key!$J$3:$L$27,3,0)} -> 4 | EG5: {=VLOOKUP(INDEX(JC,data!$AA$1),key!$J$3:$L$27,3,0)} -> 7 | EH5: =VLOOKUP(DR5,tabel_jpm,ED5+1,0) -> 8 | EI5: =VLOOKUP(DS5,tabel_jpm,EE5+1,0) -> 20 | EJ5: =VLOOKUP(DT5,tabel_jpm,EF5+1,0) -> 16 | EK5: =VLOOKUP(DU5,tabel_jpm,EG5+1,0) -> 20 | EL5: =IF(B5="Pria",VLOOKUP(AVERAGE(EH5:EK5),agreement_p,4),VLOOKUP(AVERAGE(EH5:EK5),agreement_w,4)) -> 48 | EM5: =IF(DP5<>"444","N/A",EL5) -> 48 | EN5: =VLOOKUP(DV5,tabel_jpm,ED5+1,0) -> 8 | EO5: =VLOOKUP(DW5,tabel_jpm,EE5+1,0) -> 20 | EP5: =VLOOKUP(DX5,tabel_jpm,EF5+1,0) -> 12 | EQ5: =VLOOKUP(DY5,tabel_jpm,EG5+1,0) -> 28 | ER5: =IF(B5="Pria",VLOOKUP(AVERAGE(EN5:EQ5),agreement_p,4),VLOOKUP(AVERAGE(EN5:EQ5),agreement_w,4)) -> 50 | ES5: =IF(DP5<>"444","N/A",ER5) -> 50 | ET5: =VLOOKUP(DZ5,tabel_jpm,ED5+1,0) -> 8 | EU5: =VLOOKUP(EA5,tabel_jpm,EE5+1,0) -> 28 | EV5: =VLOOKUP(EB5,tabel_jpm,EF5+1,0) -> 12 | EW5: =VLOOKUP(EC5,tabel_jpm,EG5+1,0) -> 24 | EX5: =IF(B5="Pria",VLOOKUP(AVERAGE(ET5:EW5),agreement_p,4),VLOOKUP(AVERAGE(ET5:EW5),agreement_w,4)) -> 51 | EY5: =IF(DP5<>"444","N/A",EX5) -> 51
A6: =data!A6 -> Ayub Putra Utama | B6: =data!B6 -> Pria | C6: =data!C6 | D6: =data!D6 | E6: =data!E6 | F6: =data!F6 -> profiling | G6: =data!G6 -> 3 | H6: =data!H6 -> 4 | ... W6: =data!W6 -> 24 | Y6: =VLOOKUP(G6,tableD1,2,0) -> 11 | Z6: =VLOOKUP(H6,tableI1,2,0) -> 18 | AA6: =VLOOKUP(I6,table1S,2,0) -> 22 | AB6: =VLOOKUP(J6,table1C,2,0) -> 10 | AC6: =VLOOKUP(L6,table2D,2,0) -> 15 | AD6: =VLOOKUP(M6,table2I,2,0) -> 12 | AE6: =VLOOKUP(N6,table2S,2,0) -> 31 | AF6: =VLOOKUP(O6,table2C,2,0) -> 28 | AG6: =VLOOKUP(Q6,table3D,2,0) -> 14 | AH6: =VLOOKUP(R6,table3I,2,0) -> 14 | AI6: =VLOOKUP(S6,table3S,2,0) -> 26 | AJ6: =VLOOKUP(T6,table3C,2,0) -> 19 | AL6: =VALUE(Y6&AL$2) -> 111 | AM6: =VALUE(Z6&AM$2) -> 182 | AN6: =VALUE(AA6&AN$2) -> 223 | AO6: =VALUE(AB6&AO$2) -> 104 | AQ6: =LARGE($AL6:$AO6,AQ$2) -> 223 | AR6: =LARGE($AL6:$AO6,AR$2) -> 182 | AS6: =LARGE($AL6:$AO6,AS$2) -> 111 | AT6: =LARGE($AL6:$AO6,AT$2) -> 104 | AV6: =VLOOKUP(VALUE(RIGHT(AQ6,1)),misc!$A$2:$B$5,2,0) -> S | AW6: =VLOOKUP(VALUE(RIGHT(AR6,1)),misc!$A$2:$B$5,2,0) -> I | AX6: =VLOOKUP(VALUE(RIGHT(AS6,1)),misc!$A$2:$B$5,2,0) -> D | AY6: =VLOOKUP(VALUE(RIGHT(AT6,1)),misc!$A$2:$B$5,2,0) -> C | BA6: =IF(VALUE(AQ6)>=170,AV6,"") -> S | BB6: =IF(VALUE(AR6)>=170,AW6,"") -> I | BC6: =IF(VALUE(AS6)>=170,AX6,"") | BD6: =IF(VALUE(AT6)>=170,AY6,"") | BF6: =IF(VALUE(AQ6)<170,AV6,"") | BG6: =IF(VALUE(AR6)<170,AW6,"") | BH6: =IF(VALUE(AS6)<170,AX6,"") -> D | BI6: =IF(VALUE(AT6)<170,AY6,"") -> C | BJ6: =IF(AND(Y6<17,Z6<17,AA6<17,AB6<17),1,IF(AND(Y6>=17,Z6>=17,AA6>=17,AB6>=17),2,IF(AND(Y6>12,Y6<21,Z6>12,Z6<21,AA6>12,AA6<21,AB6>12,AB6<21),3,4))) -> 4 | BK6: =TRIM(BA6&BB6&BC6&BD6) -> SI | BN6: =VALUE(AC6&BN$2) -> 151 | BO6: =VALUE(AD6&BO$2) -> 122 | BP6: =VALUE(AE6&BP$2) -> 313 | BQ6: =VALUE(AF6&BQ$2) -> 284 | BS6: =LARGE($BN6:$BQ6,BS$2) -> 313 | BT6: =LARGE($BN6:$BQ6,BT$2) -> 284 | BU6: =LARGE($BN6:$BQ6,BU$2) -> 151 | BV6: =LARGE($BN6:$BQ6,BV$2) -> 122 | BX6: =VLOOKUP(VALUE(RIGHT(BS6,1)),misc!$A$2:$B$5,2,0) -> S | BY6: =VLOOKUP(VALUE(RIGHT(BT6,1)),misc!$A$2:$B$5,2,0) -> C | BZ6: =VLOOKUP(VALUE(RIGHT(BU6,1)),misc!$A$2:$B$5,2,0) -> D | CA6: =VLOOKUP(VALUE(RIGHT(BV6,1)),misc!$A$2:$B$5,2,0) -> I | CC6: =IF(VALUE(BS6)>=170,BX6,"") -> S | CD6: =IF(VALUE(BT6)>=170,BY6,"") -> C | CE6: =IF(VALUE(BU6)>=170,BZ6,"") | CF6: =IF(VALUE(BV6)>=170,CA6,"") | CH6: =IF(VALUE(BS6)<170,BX6,"") | CI6: =IF(VALUE(BT6)<170,BY6,"") | CJ6: =IF(VALUE(BU6)<170,BZ6,"") -> D | CK6: =IF(VALUE(BV6)<170,CA6,"") -> I | CL6: =IF(AND(AC6<17,AD6<17,AE6<17,AF6<17),1,IF(AND(AC6>=17,AD6>=17,AE6>=17,AF6>=17),2,IF(AND(AC6>12,AC6<21,AD6>12,AD6<21,AE6>12,AE6<21,AF6>12,AF6<21),3,4))) -> 4 | CM6: =TRIM(CC6&CD6&CE6&CF6) -> SC | CP6: =VALUE(AG6&CP$2) -> 141 | CQ6: =VALUE(AH6&CQ$2) -> 142 | CR6: =VALUE(AI6&CR$2) -> 263 | CS6: =VALUE(AJ6&CS$2) -> 194 | CU6: =LARGE($CP6:$CS6,CU$2) -> 263 | CV6: =LARGE($CP6:$CS6,CV$2) -> 194 | CW6: =LARGE($CP6:$CS6,CW$2) -> 142 | CX6: =LARGE($CP6:$CS6,CX$2) -> 141 | CZ6: =VLOOKUP(VALUE(RIGHT(CU6,1)),misc!$A$2:$B$5,2,0) -> S | DA6: =VLOOKUP(VALUE(RIGHT(CV6,1)),misc!$A$2:$B$5,2,0) -> C | DB6: =VLOOKUP(VALUE(RIGHT(CW6,1)),misc!$A$2:$B$5,2,0) -> I | DC6: =VLOOKUP(VALUE(RIGHT(CX6,1)),misc!$A$2:$B$5,2,0) -> D | DE6: =IF(VALUE(CU6)>=170,CZ6,"") -> S | DF6: =IF(VALUE(CV6)>=170,DA6,"") -> C | DG6: =IF(VALUE(CW6)>=170,DB6,"") | DH6: =IF(VALUE(CX6)>=170,DC6,"") | DJ6: =IF(VALUE(CU6)<170,CZ6,"") | DK6: =IF(VALUE(CV6)<170,DA6,"") | DL6: =IF(VALUE(CW6)<170,DB6,"") -> I | DM6: =IF(VALUE(CX6)<170,DC6,"") -> D | DN6: =IF(AND(AG6<17,AH6<17,AI6<17,AJ6<17),1,IF(AND(AG6>=17,AH6>=17,AI6>=17,AJ6>=17),2,IF(AND(AG6>12,AG6<21,AH6>12,AH6<21,AI6>12,AI6<21,AJ6>12,AJ6<21),3,4))) -> 4 | DO6: =TRIM(DE6&DF6&DG6&DH6) -> SC | DP6: =BJ6&CL6&DN6 -> 444 | DQ6: =A6&G6&H6&I6&J6&L6&M6&N6&O6 -> Ayub Putra Utama34827612 | DR6: =VLOOKUP(G6,tableD1,3,0) -> 3 | DS6: =VLOOKUP(H6,tableI1,3,0) -> 5 | DT6: =VLOOKUP(I6,table1S,3,0) -> 6 | DU6: =VLOOKUP(J6,table1C,3,0) -> 3 | DV6: =VLOOKUP(L6,table2D,3,0) -> 4 | DW6: =VLOOKUP(M6,table2I,3,0) -> 3 | DX6: =VLOOKUP(N6,table2S,3,0) -> 8 | DY6: =VLOOKUP(O6,table2C,3,0) -> 7 | DZ6: =VLOOKUP(Q6,table3D,3,0) -> 4 | EA6: =VLOOKUP(R6,table3I,3,0) -> 4 | EB6: =VLOOKUP(S6,table3S,3,0) -> 7 | EC6: =VLOOKUP(T6,table3C,3,0) -> 5 | ED6: {=VLOOKUP(INDEX(JD,data!$AA$1),key!$J$3:$L$27,3,0)} -> 6 | EE6: {=VLOOKUP(INDEX(JI,data!$AA$1),key!$J$3:$L$27,3,0)} -> 4 | EF6: {=VLOOKUP(INDEX(JS,data!$AA$1),key!$J$3:$L$27,3,0)} -> 4 | EG6: {=VLOOKUP(INDEX(JC,data!$AA$1),key!$J$3:$L$27,3,0)} -> 7 | EH6: =VLOOKUP(DR6,tabel_jpm,ED6+1,0) -> 16 | EI6: =VLOOKUP(DS6,tabel_jpm,EE6+1,0) -> 24 | EJ6: =VLOOKUP(DT6,tabel_jpm,EF6+1,0) -> 20 | EK6: =VLOOKUP(DU6,tabel_jpm,EG6+1,0) -> 12 | EL6: =IF(B6="Pria",VLOOKUP(AVERAGE(EH6:EK6),agreement_p,4),VLOOKUP(AVERAGE(EH6:EK6),agreement_w,4)) -> 57 | EM6: =IF(DP6<>"444","N/A",EL6) -> 57 | EN6: =VLOOKUP(DV6,tabel_jpm,ED6+1,0) -> 20 | EO6: =VLOOKUP(DW6,tabel_jpm,EE6+1,0) -> 24 | EP6: =VLOOKUP(DX6,tabel_jpm,EF6+1,0) -> 12 | EQ6: =VLOOKUP(DY6,tabel_jpm,EG6+1,0) -> 28 | ER6: =IF(B6="Pria",VLOOKUP(AVERAGE(EN6:EQ6),agreement_p,4),VLOOKUP(AVERAGE(EN6:EQ6),agreement_w,4)) -> 62 | ES6: =IF(DP6<>"444","N/A",ER6) -> 62 | ET6: =VLOOKUP(DZ6,tabel_jpm,ED6+1,0) -> 20 | EU6: =VLOOKUP(EA6,tabel_jpm,EE6+1,0) -> 28 | EV6: =VLOOKUP(EB6,tabel_jpm,EF6+1,0) -> 16 | EW6: =VLOOKUP(EC6,tabel_jpm,EG6+1,0) -> 20 | EX6: =IF(B6="Pria",VLOOKUP(AVERAGE(ET6:EW6),agreement_p,4),VLOOKUP(AVERAGE(ET6:EW6),agreement_w,4)) -> 62 | EY6: =IF(DP6<>"444","N/A",EX6) -> 62
A7: =data!A7 | B7: =data!B7 | C7: =data!C7 | D7: =data!D7 | E7: =data!E7 | F7: =data!F7 | G7: =data!G7 | H7: =data!H7 | ... W7: =data!W7 | Y7: =VLOOKUP(G7,tableD1,2,0) -> 4 | Z7: =VLOOKUP(H7,tableI1,2,0) -> 3 | AA7: =VLOOKUP(I7,table1S,2,0) -> 5 | AB7: =VLOOKUP(J7,table1C,2,0) -> 4 | AC7: =VLOOKUP(L7,table2D,2,0) -> 31 | AD7: =VLOOKUP(M7,table2I,2,0) -> 31 | AE7: =VLOOKUP(N7,table2S,2,0) -> 32 | AF7: =VLOOKUP(O7,table2C,2,0) -> 32 | AG7: =VLOOKUP(Q7,table3D,2,0) -> 16 | AH7: =VLOOKUP(R7,table3I,2,0) -> 18 | AI7: =VLOOKUP(S7,table3S,2,0) -> 19 | AJ7: =VLOOKUP(T7,table3C,2,0) -> 19 | AL7: =VALUE(Y7&AL$2) -> 41 | AM7: =VALUE(Z7&AM$2) -> 32 | AN7: =VALUE(AA7&AN$2) -> 53 | AO7: =VALUE(AB7&AO$2) -> 44 | AQ7: =LARGE($AL7:$AO7,AQ$2) -> 53 | AR7: =LARGE($AL7:$AO7,AR$2) -> 44 | AS7: =LARGE($AL7:$AO7,AS$2) -> 41 | AT7: =LARGE($AL7:$AO7,AT$2) -> 32 | AV7: =VLOOKUP(VALUE(RIGHT(AQ7,1)),misc!$A$2:$B$5,2,0) -> S | AW7: =VLOOKUP(VALUE(RIGHT(AR7,1)),misc!$A$2:$B$5,2,0) -> C | AX7: =VLOOKUP(VALUE(RIGHT(AS7,1)),misc!$A$2:$B$5,2,0) -> D | AY7: =VLOOKUP(VALUE(RIGHT(AT7,1)),misc!$A$2:$B$5,2,0) -> I | BA7: =IF(VALUE(AQ7)>=170,AV7,"") | BB7: =IF(VALUE(AR7)>=170,AW7,"") | BC7: =IF(VALUE(AS7)>=170,AX7,"") | BD7: =IF(VALUE(AT7)>=170,AY7,"") | BF7: =IF(VALUE(AQ7)<170,AV7,"") -> S | BG7: =IF(VALUE(AR7)<170,AW7,"") -> C | BH7: =IF(VALUE(AS7)<170,AX7,"") -> D | BI7: =IF(VALUE(AT7)<170,AY7,"") -> I | BJ7: =IF(AND(Y7<17,Z7<17,AA7<17,AB7<17),1,IF(AND(Y7>=17,Z7>=17,AA7>=17,AB7>=17),2,IF(AND(Y7>12,Y7<21,Z7>12,Z7<21,AA7>12,AA7<21,AB7>12,AB7<21),3,4))) -> 1 | BK7: =TRIM(BA7&BB7&BC7&BD7) | BN7: =VALUE(AC7&BN$2) -> 311 | BO7: =VALUE(AD7&BO$2) -> 312 | BP7: =VALUE(AE7&BP$2) -> 323 | BQ7: =VALUE(AF7&BQ$2) -> 324 | BS7: =LARGE($BN7:$BQ7,BS$2) -> 324 | BT7: =LARGE($BN7:$BQ7,BT$2) -> 323 | BU7: =LARGE($BN7:$BQ7,BU$2) -> 312 | BV7: =LARGE($BN7:$BQ7,BV$2) -> 311 | BX7: =VLOOKUP(VALUE(RIGHT(BS7,1)),misc!$A$2:$B$5,2,0) -> C | BY7: =VLOOKUP(VALUE(RIGHT(BT7,1)),misc!$A$2:$B$5,2,0) -> S | BZ7: =VLOOKUP(VALUE(RIGHT(BU7,1)),misc!$A$2:$B$5,2,0) -> I | CA7: =VLOOKUP(VALUE(RIGHT(BV7,1)),misc!$A$2:$B$5,2,0) -> D | CC7: =IF(VALUE(BS7)>=170,BX7,"") -> C | CD7: =IF(VALUE(BT7)>=170,BY7,"") -> S | CE7: =IF(VALUE(BU7)>=170,BZ7,"") -> I | CF7: =IF(VALUE(BV7)>=170,CA7,"") -> D | CH7: =IF(VALUE(BS7)<170,BX7,"") | CI7: =IF(VALUE(BT7)<170,BY7,"") | CJ7: =IF(VALUE(BU7)<170,BZ7,"") | CK7: =IF(VALUE(BV7)<170,CA7,"") | CL7: =IF(AND(AC7<17,AD7<17,AE7<17,AF7<17),1,IF(AND(AC7>=17,AD7>=17,AE7>=17,AF7>=17),2,IF(AND(AC7>12,AC7<21,AD7>12,AD7<21,AE7>12,AE7<21,AF7>12,AF7<21),3,4))) -> 2 | CM7: =TRIM(CC7&CD7&CE7&CF7) -> CSID | CP7: =VALUE(AG7&CP$2) -> 161 | CQ7: =VALUE(AH7&CQ$2) -> 182 | CR7: =VALUE(AI7&CR$2) -> 193 | CS7: =VALUE(AJ7&CS$2) -> 194 | CU7: =LARGE($CP7:$CS7,CU$2) -> 194 | CV7: =LARGE($CP7:$CS7,CV$2) -> 193 | CW7: =LARGE($CP7:$CS7,CW$2) -> 182 | CX7: =LARGE($CP7:$CS7,CX$2) -> 161 | CZ7: =VLOOKUP(VALUE(RIGHT(CU7,1)),misc!$A$2:$B$5,2,0) -> C | DA7: =VLOOKUP(VALUE(RIGHT(CV7,1)),misc!$A$2:$B$5,2,0) -> S | DB7: =VLOOKUP(VALUE(RIGHT(CW7,1)),misc!$A$2:$B$5,2,0) -> I | DC7: =VLOOKUP(VALUE(RIGHT(CX7,1)),misc!$A$2:$B$5,2,0) -> D | DE7: =IF(VALUE(CU7)>=170,CZ7,"") -> C | DF7: =IF(VALUE(CV7)>=170,DA7,"") -> S | DG7: =IF(VALUE(CW7)>=170,DB7,"") -> I | DH7: =IF(VALUE(CX7)>=170,DC7,"") | DJ7: =IF(VALUE(CU7)<170,CZ7,"") | DK7: =IF(VALUE(CV7)<170,DA7,"") | DL7: =IF(VALUE(CW7)<170,DB7,"") | DM7: =IF(VALUE(CX7)<170,DC7,"") -> D | DN7: =IF(AND(AG7<17,AH7<17,AI7<17,AJ7<17),1,IF(AND(AG7>=17,AH7>=17,AI7>=17,AJ7>=17),2,IF(AND(AG7>12,AG7<21,AH7>12,AH7<21,AI7>12,AI7<21,AJ7>12,AJ7<21),3,4))) -> 3 | DO7: =TRIM(DE7&DF7&DG7&DH7) -> CSI | DP7: =BJ7&CL7&DN7 -> 123 | DQ7: =A7&G7&H7&I7&J7&L7&M7&N7&O7 | DR7: =VLOOKUP(G7,tableD1,3,0) -> 1 | DS7: =VLOOKUP(H7,tableI1,3,0) -> 1 | DT7: =VLOOKUP(I7,table1S,3,0) -> 2 | DU7: =VLOOKUP(J7,table1C,3,0) -> 1 | DV7: =VLOOKUP(L7,table2D,3,0) -> 8 | DW7: =VLOOKUP(M7,table2I,3,0) -> 8 | DX7: =VLOOKUP(N7,table2S,3,0) -> 8 | DY7: =VLOOKUP(O7,table2C,3,0) -> 8 | DZ7: =VLOOKUP(Q7,table3D,3,0) -> 4 | EA7: =VLOOKUP(R7,table3I,3,0) -> 5 | EB7: =VLOOKUP(S7,table3S,3,0) -> 5 | EC7: =VLOOKUP(T7,table3C,3,0) -> 5 | ED7: {=VLOOKUP(INDEX(JD,data!$AA$1),key!$J$3:$L$27,3,0)} -> 6 | EE7: {=VLOOKUP(INDEX(JI,data!$AA$1),key!$J$3:$L$27,3,0)} -> 4 | EF7: {=VLOOKUP(INDEX(JS,data!$AA$1),key!$J$3:$L$27,3,0)} -> 4 | EG7: {=VLOOKUP(INDEX(JC,data!$AA$1),key!$J$3:$L$27,3,0)} -> 7 | EH7: =VLOOKUP(DR7,tabel_jpm,ED7+1,0) -> 8 | EI7: =VLOOKUP(DS7,tabel_jpm,EE7+1,0) -> 16 | EJ7: =VLOOKUP(DT7,tabel_jpm,EF7+1,0) -> 20 | EK7: =VLOOKUP(DU7,tabel_jpm,EG7+1,0) -> 4 | EL7: =IF(B7="Pria",VLOOKUP(AVERAGE(EH7:EK7),agreement_p,4),VLOOKUP(AVERAGE(EH7:EK7),agreement_w,4)) -> 32 | EM7: =IF(DP7<>"444","N/A",EL7) -> N/A | EN7: =VLOOKUP(DV7,tabel_jpm,ED7+1,0) -> 20 | EO7: =VLOOKUP(DW7,tabel_jpm,EE7+1,0) -> 12 | EP7: =VLOOKUP(DX7,tabel_jpm,EF7+1,0) -> 12 | EQ7: =VLOOKUP(DY7,tabel_jpm,EG7+1,0) -> 24 | ER7: =IF(B7="Pria",VLOOKUP(AVERAGE(EN7:EQ7),agreement_p,4),VLOOKUP(AVERAGE(EN7:EQ7),agreement_w,4)) -> 50 | ES7: =IF(DP7<>"444","N/A",ER7) -> N/A | ET7: =VLOOKUP(DZ7,tabel_jpm,ED7+1,0) -> 20 | EU7: =VLOOKUP(EA7,tabel_jpm,EE7+1,0) -> 24 | EV7: =VLOOKUP(EB7,tabel_jpm,EF7+1,0) -> 24 | EW7: =VLOOKUP(EC7,tabel_jpm,EG7+1,0) -> 20 | EX7: =IF(B7="Pria",VLOOKUP(AVERAGE(ET7:EW7),agreement_p,4),VLOOKUP(AVERAGE(ET7:EW7),agreement_w,4)) -> 68 | EY7: =IF(DP7<>"444","N/A",EX7) -> N/A
